Workbook

Sheet CALCULO GERAL
C3: 7.968 | D3: =C3/2500 -> 0.0031872 | F3: =1.82 -> 1.82 | J3: =D23/C20 -> 8.0049385 | K3: =J3/C11 -> 1.594927
F4: 2.18 | G4: =F4/F3-1 -> 0.1978022 | K4: =G10*K3 -> 10048.04
A5: =23841.99/25500 -> 0.93498 | B5: CÁLCULO DE PREÇOS PROCESSO | I5: CALCULO ITEM 1 | M5: =25315.76-27845.34 -> -2529.58 | R5: CALCULO ITEM 2 | AA5: BASE DE CALCULO CUSTOS | AG5: CALCIULAR PREÇO FINAL
I8: IMPORTAÇÃO - MG | R8: IMPORTAÇÃO - MG | V8: VENDA - INTERESTADUAL | AG8: Dolar Final | AH8: VENDA EM DÓLAR | AI8: Preço Final R$ | AJ8: Container | AK8: Valor Final
I9: Descrição | M9: CUSTO TOTAL UNITÁRIO | O9: =K41 -> 3.817462 | R9: Descrição | S9: % | AC9: ITEM 1 | AD9: ITEM 2 | AG9: =(5.4571*0.2)+(5.2137*0.8) -> 5.26238 | AH9: =C22 -> 0.83 | AI9: =AG9*AH9 -> 4.3677754 | AJ9: 117.421 metros | AK9: =AI9*K12 -> 1091943.9
B10: TRANSPORTE | C10: IBITINGA | D10: OPERAÇÃO | E10: INTER | F10: FRETE INTERNAC. USD | G10: 6300 | I10: NCM | K10: =F14 -> 5407.52.10 | M10: (-) CRÉDITOS S/ IMPORT | O10: =SUM(O11:O14) -> 0.32779189 | R10: NCM | T10: =F29 -> 5407.52.10 | V10: CUSTO TOTAL UNITÁRIO | X10: =T41 -> 4.494633 | AB10: CELULA NCM | AC10: 80 | AD10: 80 | AG10: 5,4571x 20 por cento da entrada
A11: =C11+0.15 -> 5.169 | B11: DÓLAR FISCAL | C11: 5.019 | D11: COMISSÃO | E11: 0.02 | F11: CAPADIDADE CNTR | G11: 1 | I11: Vr. FOB Unitário | K11: =C17 -> 0.47 | M11: (-) IPI | O11: =K43/$K$12 -> 0 | R11: Vr. FOB Unitário | T11: =C32 -> 0.56 | V11: (-) CRÉDITOS S/ IMPORT | X11: =SUM(X12:X15) -> 0 | AB11: CELULA ICMS | AC11: 2
B12: MESES | C12: 5 | D12: JUROS | E12: =G12/12 -> 0.012083333 | F12: JUROS A.A. | G12: 0.145 | I12: Quantidade | K12: =C16 -> 250000 | M12: (-) PIS | O12: =K44/$K$12 -> 0.05484964 | R12: Quantidade | T12: =C31 -> 115000 | V12: (-) IPI | X12: =T43/$T$12 -> 0 | AA12: 1 | AB12: CABOTAGEM | AC12: 0.14 | AD12: INTRA | AE12: 0.14 | AG12: 5,2137 x 80 por cento do saldo | AN12: 8308.42 | AO12: =AO14/AN14*AN12 -> 8420.5822 | AP12: =AO12-AN12 -> 112.16217
I13: Vr. FOB TOTAL | K13: =K12*K11 -> 117500 | M13: (-) COFINS | O13: =K45/$K$12 -> 0.27294225 | R13: Vr. FOB TOTAL | T13: =T12*T11 -> 64400 | V13: (-) PIS | X13: =T44/$T$12 -> 0 | AA13: 2 | AB13: IBITINGA | AC13: 0.015 | AD13: INTER | AE13: 0.015 | AN13: 4579.16 | AO13: =AO14/AN14*AN13 -> 4640.9778 | AP13: =AO13-AN13 -> 61.817832
A14: de | B14: PRODUTO 1 | C14: TEC MIC 85GSM ESTAMPADO 250CM | E14: NCM | F14: =VLOOKUP(C14,'NCMS E ALÍQUOTAS'!B2:C2225,2,FALSE) -> 5407.52.10 | I14: TX CONVERSÃO FISCAL | K14: =C11 -> 5.019 | M14: (-) ICMS | O14: =K46/$K$12 -> 0 | R14: TX CONVERSÃO FISCAL | T14: =C11 -> 5.019 | V14: (-) COFINS | X14: =T45/$T$12 -> 0 | AA14: 3 | AB14: MINAS | AC14: 1 | AN14: 12887.58 | AO14: 13061.56
B15: QUANTIDADE CNTR | C15: 2 | D15: =$C$15/$G$11 -> 2 | G15: =158*65*146/1000000 -> 1.49942 | I15: Total FOB R$ | K15: =K13*K14 -> 589732.5 | M15: CUSTO FINAL | O15: =O9-O10 -> 3.4896701 | P15: =P16-K16 -> 1580.985 | R15: Total FOB R$ | T15: =T13*T14 -> 323223.6 | V15: (-) ICMS | X15: =T46/$T$12 -> 0 | AB15: CABOTAGEM
A16: =C16 -> 250000 | B16: QUANTIDADE | C16: 250000 | D16: QUANTIDADE 1x40 | E16: 125000 | F16: =C16*0.8*0.255 -> 51000 | G16: =G15*50 -> 74.971 | I16: Frete Internacional | J16: =C19 -> 12600 | K16: =J16*K14 -> 63239.4 | M16: Outros Gastos | O16: =SUM(O17:O23) -> 0.0833154 | P16: =K16*1.025 -> 64820.385 | R16: Frete Internacional | S16: =C34 -> 6300 | T16: =S16*T14 -> 31619.7 | V16: CUSTO FINAL | X16: =X10-X11 -> 4.494633 | AB16: CALCULO TRANSPORTADORA IDA | AE16: CABOTAGEM
A17: =C17 -> 0.47 | B17: VALOR FOB | C17: 0.47 | D17: VALOR FOB TABELA | E17: =VLOOKUP(C14,'TABELA MATRIZ MG'!$A$2:$Y$329,25,FALSE) -> 0.519 | F17: Xx | G17: =VLOOKUP(C14,'TABELA MATRIZ MG'!$A$2:$Y$438,24,FALSE) -> 0.48 | I17: Capatazia | N17: 0 | O17: =N17/K12 -> 0 | R17: Capatazia | T17: 0 | V17: Outros Gastos | X17: =SUM(X18:X33) -> 0.0983724 | AB17: FRETE PESO | AC17: 2966 | AD17: =AC17 -> 2966 | AE17: 15000
A18: =C17 -> 0.47 | B18: TOTAL FOB | C18: =C16*C17 -> 117500 | D18: TOTAL FOB R$ | E18: =C18*C11 -> 589732.5 | F18: 0.2 | G18: =E18*0.2 -> 117946.5 | I18: Valor CIF | K18: =SUM(K15:K17) -> 652971.9 | M18: Comissão de vendas | N18: =E11 -> 0.02 | O18: =N18*G22 -> 0.0833154 | P18: =O18*K12 -> 20828.85 | R18: Valor aduaneiro | T18: =SUM(T15:T17) -> 354843.3 | W18: 0 | X18: =W18/T12 -> 0 | AB18: PEDÁGIO | AC18: 61.8 | AD18: =AC18 -> 61.8
A19: =A16*A17 -> 117500 | B19: FRETE INTERNAC. USD | C19: =G10*D15 -> 12600 | D19: FRETE INTERNAC. R$ | E19: =C19*C11 -> 63239.4 | F19: 0.8 | G19: =E18*0.8 -> 471786 | I19: Imp. Importação | J19: =VLOOKUP($C$14,'NCMS E ALÍQUOTAS'!$B$2:$O$2225,3,FALSE) -> 0.26 | K19: =$K$18*$J$19 -> 169772.69 | O19: =N19/K12 -> 0 | R19: Imp. Importação | S19: =VLOOKUP($C$29,'NCMS E ALÍQUOTAS'!$B$2:$O$2225,3,FALSE) -> 0.26 | T19: =S19*T18 -> 92259.258 | V19: Comissão de vendas | W19: =E11 -> 0.02 | X19: =W19*G37 -> 0.0983724 | Y19: =X19*$T$12 -> 11312.826 | AB19: AD. VALOREM | AD19: =AC19*K24 -> 0
A20: =A16*A18 -> 117500 | B20: Total CIF USD | C20: =C19+C18 -> 130100 | D20: Total CIF R$ | E20: =C20*C11 -> 652971.9 | F20: CUSTO EM USD | G20: CUSTO EM REAIS | I20: IPI | J20: =VLOOKUP($C$14,'NCMS E ALÍQUOTAS'!$B$2:$O$2225,4,FALSE) -> 0 | K20: =$K$18*$J$20 -> 0 | M20: Operador Logistico | N20: 0 | O20: =N20/K12 -> 0 | P20: =15152.3+4237.51+19518.22+4079.56+2572.48 -> 45560.07 | R20: IPI | S20: =VLOOKUP($C$29,'NCMS E ALÍQUOTAS'!$B$2:$O$2225,4,FALSE) -> 0 | T20: =S20*$T$18 -> 0 | V20: Administração | X20: =W20/T12 -> 0 | AB20: ADICIONAL 25 TON | AC20: 0.15 | AD20: =AC17*AC20 -> 444.9 | AL20: =2.18*25000 -> 54500
A21: =A19/A20-1 -> 0 | B21: CUSTO PROCESSO | D21: =K40+P28+P29+P31+P18+P33+P36+P37+P38-K42 -> 1013140.7 | F21: =G21/$C$11 -> 0.80744425 | G21: =D21/C16 -> 4.0525627 | I21: PIS | J21: =VLOOKUP($C$14,'NCMS E ALÍQUOTAS'!$B$2:$O$2225,5,FALSE) -> 0.021 | K21: =$K$18*$J$21 -> 13712.41 | M21: Contador | N21: 0 | O21: =N21/K12 -> 0 | P21: =P20+K47 -> 917977.59 | R21: PIS | S21: =VLOOKUP($C$29,'NCMS E ALÍQUOTAS'!$B$2:$O$2225,5,FALSE) -> 0.021 | T21: =S21*$T$18 -> 7451.7093 | V21: Operador Logistico | W21: 0 | X21: =W21/T12 -> 0 | AB21: ICMS | AC21: 0.12 | AD21: =SUM(AD17:AD20)*AC21/0.88 -> 473.55 | AL21: =AL20*C11 -> 273535.5 | AN21: =22 -> 22
A22: =A19-A20 -> 0 | B22: PV em USD | C22: 0.83 | D22: PV TABELA | E22: =C22*C16 -> 207500 | F22: PV em R$ | G22: =$C$22*$C$11 -> 4.16577 | I22: COFINS | J22: =VLOOKUP($C$14,'NCMS E ALÍQUOTAS'!$B$2:$O$2225,6,FALSE) -> 0.1045 | K22: =$K$18*$J$22 -> 68235.564 | O22: =N22/K13 -> 0 | P22: =271970.98 -> 271970.98 | R22: COFINS | S22: =VLOOKUP($C$29,'NCMS E ALÍQUOTAS'!$B$2:$O$2225,6,FALSE) -> 0.1045 | T22: =S22*$T$18 -> 37081.125 | V22: Contador | X22: =W22/T12 -> 0 | AB22: TOTAL | AD22: =SUM(AD17:AD20)/0.88 -> 3946.25 | AN22: =AN21-2.2 -> 19.8 | AP22: 60
A23: =A22*A11 -> 0 | B23: 0.84 | D23: =G22*C16 -> 1041442.5 | F23: =G23/C11 -> 62250 | G23: =D23*0.3 -> 312432.75 | I23: Total Valor Aduaneiro | K23: =SUM(K18:K22) -> 904692.57 | O23: 0 | P23: =P22-P21 -> -646006.61 | R23: Total Valor Aduaneiro | T23: =SUM(T18:T22) -> 491635.39 | V23: Salários | X23: =W23/T13 -> 0 | AB23: IBITINGA | AN23: =G22/AN21 -> 0.18935318 | AP23: 25000
A24: =A23/D23 -> 0 | B24: MARGEM | C24: =E24/D23 -> 0.0271756 | E24: =D23-D21-A23 -> 28301.825 | F24: 0.8 | G24: =D23*0.7 -> 729009.75 | I24: BC ICMS | K24: =(SUM($K$18:$K$22)+$K$26+$K$27)/(1-$J$25) -> 909964.51 | M24: CUSTO TOTAL UNITÁRIO ANTES DA NOTA | O24: =O15+O16+O28+O29+O31+O33+O20+O21 -> 4.0150258 | P24: =O24*K12 -> 1003756.4 | R24: BC ICMS | T24: =(SUM($T$18:$T$22)+$T$26+$T$27)/(1-$S$25) -> 494340.4 | V24: xxx | W24: 0 | X24: =W24/T14 -> 0 | AB24: CALCULO TRANSPORTADORA RETORNO | AP24: =AP23 -> 25000
I25: ICMS | J25: 0 | K25: =K24*J25 -> 0 | M25: Valor Unitário USD / tx dolar di | O25: =O24/K14 -> 0.79996528 | P25: =O25*K12 -> 199991.32 | R25: ICMS | S25: 0 | T25: =T24*S25 -> 0 | V25: xxx | X25: 0 | AB25: FRETE PESO | AC25: 2966 | AD25: =AC25/1.3 -> 2281.5385
B26: PV em USD | C26: =(C27+G23)/C16/C11 -> 0.8659607 | D26: =G26*C16 -> 1086564.2 | F26: PV em R$ | G26: =$C$26*$C$11 -> 4.3462567 | I26: Siscomex | K26: =115.67+38.56*2 -> 192.79 | M26: Margem | N26: =O26/O24 -> 0.037545026 | O26: =O39-O24 -> 0.15074425 | P26: =N26*P39 -> 39100.986 | R26: Siscomex | T26: =115.67+38.56 -> 154.23 | V26: xxx | X26: 0 | AB26: PEDÁGIO | AC26: 197 | AD26: =AC26 -> 197 | AG26: =670000 -> 670000
C27: =FV(E12,C12,,G24)*-1 -> 774131.43 | E27: =D26-D21-A23 -> 73423.508 | F27: =29211.53 -> 29211.53 | G27: =F27-E24 -> 909.7049 | I27: AFRMM | J27: 0.08 | K27: =(K16)*J27+20 -> 5079.152 | M27: Base de Cálculo PIS/COFINS | O27: =G22-O33-O31 -> 4.1032835 | P27: =P24*N29 -> 76285.489 | R27: AFRMM | S27: 0.08 | T27: =(T16+T17)*S27+21.2 -> 2550.776 | V27: xxx | X27: 0 | AB27: AD. VALOREM | AC27: 0.001 | AD27: =AC27*K24 -> 909.96451 | AG27: =AG26*0.001 -> 670 | AH27: 570000
C28: =20000*8 -> 160000 | G28: =G27/2 -> 454.85245 | I28: S.D.A./Despachante | K28: =AD43*$D$15 -> 5000 | M28: PIS | N28: 0.0165 | O28: =$O$27*N28 -> 0.067704177 | P28: =O28*$K$12 -> 16926.044 | R28: S.D.A./Despachante | T28: =AD43*$D$30 -> 2500 | V28: xxx | X28: 0 | AB28: ADICIONAL 25 TON | AC28: 0.15 | AD28: =AC25*AC28 -> 444.9 | AH28: =AH27*0.001 -> 570
B29: PRODUTO 2 | C29: TEC MIC 85GSM TINTO 250CM | E29: NCM | F29: =VLOOKUP(C29,'NCMS E ALÍQUOTAS'!$B$3:$C$254,2,FALSE) -> 5407.52.10 | I29: Diferença frete internacional | J29: =K14*1.025 -> 5.144475 | K29: =(J16*J29)-K16 -> 1580.985 | M29: COFINS | N29: 0.076 | O29: =$O$27*N29 -> 0.31184954 | P29: =O29*$K$12 -> 77962.386 | R29: Diferença frete internacional | S29: =T14*1.02 -> 5.11938 | T29: =(S16*S29)-T16 -> 632.394 | V29: xxx | X29: 0 | AB29: ICMS | AC29: 0.12 | AD29: =SUM(AD25:AD28)*AC29/0.88 -> 522.73677
A30: =C30 -> 1 | B30: QUANTIDADE CNTR | C30: 1 | D30: =$C$30/$G$11 -> 1 | I30: Valores Agente de cargas | K30: =AD45*$D$15 -> 3600 | M30: Base de Cálculo ICMS | O30: =G22-O33 -> 4.16577 | P30: =P24*N31 -> 15056.347 | R30: Valores Agente de cargas | T30: =AD45*$D$30 -> 1800 | V30: xxx | X30: 0 | AB30: TOTAL | AD30: =SUM(AD25:AD28)/0.88 -> 4356.1397
A31: =C31 -> 115000 | B31: QUANTIDADE | C31: 115000 | D31: QUANTIDADE 1x40 | E31: =VLOOKUP(C29,'TABELA MATRIZ MG'!$A$2:$Y$329,14,FALSE) -> 120000 | F31: =C31*0.85*0.28 -> 27370 | I31: Armazenagem PORTO | K31: =AD46*$D$15 -> 5200 | M31: ICMS | N31: 0.015 | O31: =$G$22*$N$31 -> 0.06248655 | P31: =O31*$K$12 -> 15621.638 | R31: Armazenagem PORTO | T31: =AD46*$D$30 -> 2600 | V31: xxx | X31: 0
A32: =C32 -> 0.56 | B32: VALOR FOB | C32: 0.56 | D32: VALOR FOB TABELA | E32: =VLOOKUP(C29,'TABELA MATRIZ MG'!$A$2:$Y$329,25,FALSE) -> 0.489375 | F32: MENOR FOB | G32: =VLOOKUP(C29,'TABELA MATRIZ MG'!$A$2:$BN$329,24,FALSE) -> 0.455 | I32: Capatazia | K32: =AD47*$D$15 -> 2020 | M32: BC IPI | N32: 0.04 | O32: =G22/(1+N33) -> 4.16577 | R32: Capatazia | T32: =AD47*$D$30 -> 1010 | V32: xxx | X32: 0 | AB32: CALCULO TRANSPORTADORA - IBITINGA
A33: =C32 -> 0.56 | B33: TOTAL FOB | C33: =C31*C32 -> 64400 | D33: TOTAL FOB R$ | E33: =C33*C11 -> 323223.6 | F33: 0.2 | G33: =E33*0.2 -> 64644.72 | I33: Custo Desembaraço - Santos | K33: =K23+SUM(K25:K32) -> 927365.49 | M33: IPI | N33: =J20 -> 0 | O33: =N33*O32 -> 0 | P33: =O33*$K$12 -> 0 | R33: Custo Desembaraço - Santos | T33: =T23+SUM(T25:T32) -> 502882.79 | V33: xxx | X33: 0 | AB33: FRETE PESO | AC33: 6316 | AD33: =AC33 -> 6316
A34: =A31*A32 -> 64400 | B34: FRETE INTERNAC. USD | C34: =G10*D30 -> 6300 | D34: FRETE INTERNAC. R$ | E34: =C34*C11 -> 31619.7 | F34: 0.8 | I34: Frete Interno | K34: =AD49*$D$15 -> 26000 | O34: =O24+O28+O29+O31 -> 4.457066 | P34: 0 | R34: Frete Interno - Pouso Alegre | T34: =AD49*$D$30 -> 13000 | V34: CUSTO TOTAL UNITÁRIO | X34: =X16+X17+X39+X40+X42+X44+X47+X48+X49 -> 4.9380589 | Y34: =X34*T12 -> 567876.77 | AB34: PEDÁGIO | AC34: 866.8 | AD34: =AC34 -> 866.8
A35: =A31*A33 -> 64400 | B35: Total CIF USD | C35: =C34+C33 -> 70700 | D35: Total CIF R$ | E35: =C35*C11 -> 354843.3 | F35: CUSTO EM USD | G35: CUSTO EM REAIS | M35: Base de Calculo lucro presumido | O35: =P26 -> 39100.986 | P35: 59999.99 | V35: Valor Unitário USD / tx dolar di | X35: =X34/T14 -> 0.98387306 | AB35: AD. VALOREM | AC35: 0.001 | AD35: =AC35*(K33+T33) -> 1430.2483
A36: =A35/A34-1 -> 0 | B36: CUSTO PROCESSO | D36: =T47+Y19+Y39+Y40+Y42+Y44+Y47+Y48+Y49-T43+Y57 -> 567876.77 | F36: =G36/$C$11 -> 0.98387306 | G36: =D36/C31 -> 4.9380589 | I36: Operador Logistico | K36: 1000 | M36: CCSLL | N36: 0.09 | O36: =P36/$K$12 -> 0.014076355 | P36: =O35*N36 -> 3519.0887 | R36: Operador Logistico | T36: 1000 | V36: Margem | W36: =X36/X34 -> -0.0039365397 | X36: =X37-X34 -> -0.019438865 | Y36: =W36*Y37 -> -2226.6694 | AB36: ADICIONAL 25 TON | AC36: 0.15 | AD36: =AC33*AC36 -> 947.4
A37: =A34-A35 -> 0 | B37: PV em USD | C37: 0.98 | D37: PV TABELA | E37: =VLOOKUP(C29,'TABELA MATRIZ MG'!$A$2:$BN$329,66,FALSE) -> 0.87 | F37: PV em R$ | G37: =$C$37*$C$11 -> 4.91862 | I37: Operação de carga e descarga | K37: 0 | M37: IR | N37: 0.15 | O37: =P37/$K$12 -> 0.023460592 | P37: =N37*O35 -> 5865.1479 | R37: Operação de carga e descarga | V37: PREÇO DE VENDA S/ Impostos | X37: =G37 -> 4.91862 | Y37: =X37*T12 -> 565641.3 | AB37: ICMS | AC37: 0.12 | AD37: =SUM(AD33:AD36)*AC37/0.88 -> 1303.6975
A38: =A37*A26 -> 0 | B38: TOTAL VENDA | D38: =G37*C31 -> 565641.3 | F38: 0.2 | G38: =D38*0.2 -> 113128.26 | I38: coleta vazio | K38: 0 | M38: adicional de IR | N38: 0.1 | O38: =P38/$K$12 -> 0 | P38: =IF(O35>=P35,(O35-P35)*N38,IF(O35<P35,P34*N38)) -> 0 | R38: coleta vazio | V38: Base de Cálculo PIS/COFINS | X38: =G37-X44-X42 -> 4.8448407 | AB38: TOTAL | AD38: =SUM(AD33:AD36)+AD22 -> 13506.698
B39: MARGEM | C39: =E39/D38 -> -0.0039520973 | D39: LUCRO | E39: =D38-D36 -> -2235.4694 | F39: 0.8 | G39: =D38*0.8 -> 452513.04 | I39: CABOTAGEM | K39: 0 | M39: PREÇO DE VENDA | N39: =O39/5.45 -> 0.76436147 | O39: =G22 -> 4.16577 | P39: =O39*K12 -> 1041442.5 | R39: CABOTAGEM | T39: =IF(C10="CABOTAGEM",AE17,IF(C10="IBITINGA",AE32,IF(C10="MINAS",AE22)))*$D$30 -> 0 | V39: PIS | W39: =VLOOKUP($C$29,'NCMS E ALÍQUOTAS'!$B$2:$O$2225,7,FALSE) -> 0.0065 | X39: =$X$38*W39 -> 0.031491465 | Y39: =X39*$T$12 -> 3621.5184
E40: =E39-A35 -> -66635.469 | I40: Custo Processo | K40: =SUM(K33:K39) -> 954365.49 | M40: Base de Calculo DIFAL | O40: =D23+P33 -> 1041442.5 | P40: =O40/0.82 -> 1270051.8 | R40: Custo Processo | T40: =SUM(T33:T39) -> 516882.79 | V40: COFINS | W40: =VLOOKUP($C$29,'NCMS E ALÍQUOTAS'!$B$2:$O$2225,8,FALSE) -> 0.03 | X40: =$X$38*W40 -> 0.14534522 | Y40: =X40*$T$12 -> 16714.7
B41: TOTAL VENDA | E41: =D38+D23 -> 1607083.8 | I41: Custo Total Unitário | K41: =K40/K12 -> 3.817462 | M41: icms difal | N41: 0.18 | P41: =P40*N41 -> 228609.33 | R41: Custo Total Unitário | T41: =T40/T12 -> 4.494633 | V41: Base de Cálculo ICMS | X41: =P21-X44 -> 917977.59
B42: LUCRO OPERAÇÃO | E42: =E39+E24 -> 26066.356 | F42: =E42/2 -> 13033.178 | I42: (-) CRÉDITOS S/ INSUMOS | K42: =SUM(K43:K46) -> 81947.973 | M42: icms difal mg | N42: 0.04 | P42: =N42*P40 -> 50802.073 | R42: (-) CRÉDITOS S/ INSUMOS | T42: =SUM(T43:T46) -> 0 | V42: ICMS | W42: =VLOOKUP($E$10,$AD$12:$AE$13,2,FALSE) -> 0.015 | X42: =$G$37*$W$42 -> 0.0737793 | Y42: =X42*$T$12 -> 8484.6195 | AB42: CUSTOS FIXOS
I43: (-) IPI | J43: =J20 -> 0 | K43: =K20 -> 0 | M43: TOTAL DIFAL | R43: (-) IPI | T43: =T20 -> 0 | V43: BC IPI | X43: =P21/(1+W44) -> 917977.59 | AB43: S.D.A./Despachante | AD43: 2500
C44: =280/250 -> 1.12 | D44: =C32*C44 -> 0.6272 | E44: 0.98 | I44: (-) PIS | J44: =J21 -> 0.021 | K44: =$J$44*K18 -> 13712.41 | R44: (-) PIS | S44: 0 | T44: =$S$44*T18 -> 0 | V44: IPI | W44: =VLOOKUP($C$29,'NCMS E ALÍQUOTAS'!$B$2:$O$2225,4,FALSE) -> 0 | X44: =W44*X43 -> 0 | Y44: =X44*$T$12 -> 0
...

Sheet CALCULO GERAL (2)
C3: 7.968 | D3: =C3/2500 -> 0.0031872 | F3: =1.82 -> 1.82 | J3: =D23/C20 -> 8.1216353 | K3: =J3/C11 -> 1.6057327
F4: 2.18 | G4: =F4/F3-1 -> 0.1978022 | K4: =G10*K3 -> 4014.3317
A5: =23841.99/25500 -> 0.93498 | B5: CÁLCULO DE PREÇOS PROCESSO | I5: CALCULO ITEM 1 | M5: =25315.76-27845.34 -> -2529.58 | R5: CALCULO ITEM 2 | AA5: BASE DE CALCULO CUSTOS | AG5: CALCIULAR PREÇO FINAL
I8: IMPORTAÇÃO - MG | R8: IMPORTAÇÃO - MG | V8: VENDA - INTERESTADUAL | AG8: Dolar Final | AH8: VENDA EM DÓLAR | AI8: Preço Final R$ | AJ8: Container | AK8: Valor Final
I9: Descrição | M9: CUSTO TOTAL UNITÁRIO | O9: =K41 -> 4.1114742 | R9: Descrição | S9: % | AC9: ITEM 1 | AD9: ITEM 2 | AG9: =(5.4571*0.2)+(5.2137*0.8) -> 5.26238 | AH9: =C22 -> 0.9 | AI9: =AG9*AH9 -> 4.736142 | AJ9: 117.421 metros | AK9: =AI9*K12 -> 577809.32
B10: TRANSPORTE | C10: IBITINGA | D10: OPERAÇÃO | E10: INTER | F10: FRETE INTERNAC. USD | G10: 2500 | I10: NCM | K10: =F14 -> 5407.52.10 | M10: (-) CRÉDITOS S/ IMPORT | O10: =SUM(O11:O14) -> 0.35578139 | R10: NCM | T10: =F29 -> 0.12397778 | V10: CUSTO TOTAL UNITÁRIO | X10: =T41 -> #N/A | AB10: CELULA NCM | AC10: 80 | AD10: 80 | AG10: 5,4571x 20 por cento da entrada
A11: =C11+0.15 -> 5.2079 | B11: DÓLAR FISCAL | C11: 5.0579 | D11: COMISSÃO | E11: 0.02 | F11: CAPADIDADE CNTR | G11: 1 | I11: Vr. FOB Unitário | K11: =C17 -> 0.54 | M11: (-) IPI | O11: =K43/$K$12 -> 0 | R11: Vr. FOB Unitário | T11: =C32 -> 0 | V11: (-) CRÉDITOS S/ IMPORT | X11: =SUM(X12:X15) -> #N/A | AB11: CELULA ICMS | AC11: 2
B12: MESES | C12: 5 | D12: JUROS | E12: =G12/12 -> 0.012083333 | F12: JUROS A.A. | G12: 0.145 | I12: Quantidade | K12: =C16 -> 122000 | M12: (-) PIS | O12: =K44/$K$12 -> 0.059533141 | P12: =O12*K12 -> 7263.0432 | R12: Quantidade | T12: =C31 -> 0 | V12: (-) IPI | X12: =T43/$T$12 -> #N/A | AA12: 1 | AB12: CABOTAGEM | AC12: 0.14 | AD12: INTRA | AE12: 0.14 | AG12: 5,2137 x 80 por cento do saldo | AN12: 8308.42 | AO12: =AO14/AN14*AN12 -> 8420.5822 | AP12: =AO12-AN12 -> 112.16217
I13: Vr. FOB TOTAL | K13: =K12*K11 -> 65880 | M13: (-) COFINS | O13: =K45/$K$12 -> 0.29624825 | P13: =O13*K13 -> 19516.835 | R13: Vr. FOB TOTAL | T13: =T12*T11 -> 0 | V13: (-) PIS | X13: =T44/$T$12 -> #DIV/0! | AA13: 2 | AB13: IBITINGA | AC13: 0.015 | AD13: INTER | AE13: 0.015 | AN13: 4579.16 | AO13: =AO14/AN14*AN13 -> 4640.9778 | AP13: =AO13-AN13 -> 61.817832
A14: de | B14: PRODUTO 1 | C14: TEC MIC 90GSM TINTO 260CM | E14: NCM | F14: =VLOOKUP(C14,'NCMS E ALÍQUOTAS'!B2:C2225,2,FALSE) -> 5407.52.10 | I14: TX CONVERSÃO FISCAL | K14: =C11 -> 5.0579 | M14: (-) ICMS | O14: =K46/$K$12 -> 0 | R14: TX CONVERSÃO FISCAL | T14: =C11 -> 5.0579 | V14: (-) COFINS | X14: =T45/$T$12 -> #DIV/0! | AA14: 3 | AB14: MINAS | AC14: 1 | AN14: 12887.58 | AO14: 13061.56
B15: QUANTIDADE CNTR | C15: 1 | D15: =$C$15/$G$11 -> 1 | G15: =158*65*146/1000000 -> 1.49942 | I15: Total FOB R$ | K15: =K13*K14 -> 333214.45 | M15: CUSTO FINAL | O15: =O9-O10 -> 3.7556928 | P15: =P16-K16 -> 316.11875 | R15: Total FOB R$ | T15: =T13*T14 -> 0 | V15: (-) ICMS | X15: =T46/$T$12 -> #N/A | AB15: CABOTAGEM
A16: =C16 -> 122000 | B16: QUANTIDADE | C16: 122000 | D16: QUANTIDADE 1x40 | E16: 125000 | F16: =C16*0.9*0.26 -> 28548 | G16: =G15*50 -> 74.971 | I16: Frete Internacional | J16: =C19 -> 2500 | K16: =J16*K14 -> 12644.75 | M16: Outros Gastos | O16: =SUM(O17:O23) -> 0.12792745 | P16: =K16*1.025 -> 12960.869 | R16: Frete Internacional | S16: =C34 -> 0 | T16: =S16*T14 -> 0 | V16: CUSTO FINAL | X16: =X10-X11 -> #N/A | AB16: CALCULO TRANSPORTADORA IDA | AE16: CABOTAGEM
A17: =C17 -> 0.54 | B17: VALOR FOB | C17: 0.54 | D17: VALOR FOB TABELA | E17: =VLOOKUP(C14,'TABELA MATRIZ MG'!$A$2:$Y$329,25,FALSE) -> 0.48 | F17: Xx | G17: =VLOOKUP(C14,'TABELA MATRIZ MG'!$A$2:$Y$438,24,FALSE) -> 0.48 | I17: Capatazia | N17: 0 | O17: =N17/K12 -> 0 | R17: Capatazia | T17: 0 | V17: Outros Gastos | X17: =SUM(X18:X33) -> #DIV/0! | AB17: FRETE PESO | AC17: 2966 | AD17: =AC17 -> 2966 | AE17: 15000
A18: 0.54 | B18: TOTAL FOB | C18: =C16*C17 -> 65880 | D18: TOTAL FOB R$ | E18: =C18*C11 -> 333214.45 | F18: 0.2 | G18: =E18*0.2 -> 66642.89 | I18: Valor CIF | K18: =SUM(K15:K17) -> 345859.2 | M18: Comissão de vendas | N18: =E11 -> 0.02 | O18: =N18*G22 -> 0.0910422 | P18: =O18*K12 -> 11107.148 | R18: Valor aduaneiro | T18: =SUM(T15:T17) -> 0 | W18: 0 | X18: =W18/T12 -> #DIV/0! | AB18: PEDÁGIO | AC18: 61.8 | AD18: =AC18 -> 61.8
A19: =A16*A17 -> 65880 | B19: FRETE INTERNAC. USD | C19: =G10*D15 -> 2500 | D19: FRETE INTERNAC. R$ | E19: =C19*C11 -> 12644.75 | F19: 0.8 | G19: =E18*0.8 -> 266571.56 | I19: Imp. Importação | J19: =VLOOKUP($C$14,'NCMS E ALÍQUOTAS'!$B$2:$O$2225,3,FALSE) -> 0.26 | K19: =$K$18*$J$19 -> 89923.393 | O19: =N19/K12 -> 0 | R19: Imp. Importação | S19: =VLOOKUP($C$29,'NCMS E ALÍQUOTAS'!$B$2:$O$2225,3,FALSE) -> #N/A | T19: =S19*T18 -> #N/A | V19: Comissão de vendas | W19: =E11 -> 0.02 | X19: =W19*G37 -> 0 | Y19: =X19*$T$12 -> 0 | AB19: AD. VALOREM | AD19: =AC19*K24 -> 0
A20: =A16*A18 -> 65880 | B20: Total CIF USD | C20: =C19+C18 -> 68380 | D20: Total CIF R$ | E20: =C20*C11 -> 345859.2 | F20: CUSTO EM USD | G20: CUSTO EM REAIS | I20: IPI | J20: =VLOOKUP($C$14,'NCMS E ALÍQUOTAS'!$B$2:$O$2225,4,FALSE) -> 0 | K20: =$K$18*$J$20 -> 0 | M20: Operador Logistico | N20: 3000 | O20: =N20/K12 -> 0.024590164 | R20: IPI | S20: =VLOOKUP($C$29,'NCMS E ALÍQUOTAS'!$B$2:$O$2225,4,FALSE) -> #N/A | T20: =S20*$T$18 -> #N/A | V20: Administração | X20: =W20/T12 -> #DIV/0! | AB20: ADICIONAL 25 TON | AC20: 0.15 | AD20: =AC17*AC20 -> 444.9 | AL20: =2.18*25000 -> 54500
A21: =A19/A20-1 -> 0 | B21: CUSTO PROCESSO | D21: =P24+P28+P29+P31+P36+P37 -> 538162.13 | F21: =G21/$C$11 -> 0.87213369 | G21: =D21/C16 -> 4.411165 | I21: PIS | J21: =VLOOKUP($C$14,'NCMS E ALÍQUOTAS'!$B$2:$O$2225,5,FALSE) -> 0.021 | K21: =$K$18*$J$21 -> 7263.0432 | M21: Contador | N21: 1500 | O21: =N21/K12 -> 0.012295082 | R21: PIS | S21: =VLOOKUP($C$29,'NCMS E ALÍQUOTAS'!$B$2:$O$2225,5,FALSE) -> #N/A | T21: =S21*$T$18 -> #N/A | V21: Operador Logistico | W21: 0 | X21: =W21/T12 -> #DIV/0! | AB21: ICMS | AC21: 0.12 | AD21: =SUM(AD17:AD20)*AC21/0.88 -> 473.55 | AL21: =AL20*C11 -> 275655.55 | AN21: =22 -> 22
A22: =A20-A19 -> 0 | B22: PV em USD | C22: 0.9 | D22: PV TABELA | E22: =C22*C16 -> 109800 | F22: PV em R$ | G22: =$C$22*$C$11 -> 4.55211 | I22: COFINS | J22: =VLOOKUP($C$14,'NCMS E ALÍQUOTAS'!$B$2:$O$2225,6,FALSE) -> 0.1045 | K22: =$K$18*$J$22 -> 36142.287 | O22: =N22/K13 -> 0 | R22: COFINS | S22: =VLOOKUP($C$29,'NCMS E ALÍQUOTAS'!$B$2:$O$2225,6,FALSE) -> #N/A | T22: =S22*$T$18 -> #N/A | V22: Contador | X22: =W22/T12 -> #DIV/0! | AB22: TOTAL | AD22: =SUM(AD17:AD20)/0.88 -> 3946.25 | AN22: =AN21-2.2 -> 19.8 | AP22: 60
A23: =A22*A11 -> 0 | D23: =G22*C16 -> 555357.42 | F23: =G23/C11 -> 32940 | G23: =D23*0.3 -> 166607.23 | I23: Total Valor Aduaneiro | K23: =SUM(K18:K22) -> 479187.92 | O23: 0 | R23: Total Valor Aduaneiro | T23: =SUM(T18:T22) -> #N/A | V23: Salários | X23: =W23/T13 -> #DIV/0! | AB23: IBITINGA | AN23: =G22/AN21 -> 0.20691409 | AP23: 25000
A24: =A23/D23 -> 0 | B24: MARGEM | C24: =E24/D23 -> 0.030962568 | E24: =D23-D21 -> 17195.292 | F24: 0.8 | G24: =D23*0.7 -> 388750.19 | I24: BC ICMS | K24: =(SUM($K$18:$K$22)+$K$26+$K$27)/(1-$J$25) -> 480373.73 | M24: CUSTO TOTAL UNITÁRIO ANTES DA NOTA | O24: =O15+O16 -> 3.8836203 | P24: =O24*K12 -> 473801.67 | R24: BC ICMS | T24: =(SUM($T$18:$T$22)+$T$26+$T$27)/(1-$S$25) -> #N/A | V24: xxx | W24: 0 | X24: =W24/T14 -> 0 | AB24: CALCULO TRANSPORTADORA RETORNO | AP24: =AP23 -> 25000
C25: =C22/C28-1 -> 0.071428571 | F25: =D23*E11 -> 11107.148 | G25: =E24*0.05 -> 859.7646 | I25: ICMS | J25: 0 | K25: =K24*J25 -> 0 | M25: Valor Unitário USD / tx dolar di | O25: =O24/K14 -> 0.76783255 | P25: =O25*K12 -> 93675.571 | R25: ICMS | S25: 0 | T25: =T24*S25 -> #N/A | V25: xxx | X25: 0 | AB25: FRETE PESO | AC25: 2966 | AD25: =AC25/1.3 -> 2281.5385
B26: PV em USD | C26: =(C27+G23)/C16/C11 -> 0.93899353 | D26: =G26*C16 -> 579418.91 | F26: PV em R$ | G26: =$C$26*$C$11 -> 4.7493354 | I26: Siscomex | K26: =115.67+38.56 -> 154.23 | M26: Margem | O26: =O34-O33-O31-O28-O29-O24 -> 0.18545397 | P26: =O26*$K$12 -> 22625.384 | R26: Siscomex | T26: =115.67+38.56 -> 154.23 | V26: xxx | X26: 0 | AB26: PEDÁGIO | AC26: 197 | AD26: =AC26 -> 197 | AG26: =670000 -> 670000
C27: =FV(E12,C12,,G24)*-1 -> 412811.69 | E27: =D26-D21 -> 41256.785 | G27: =E24*0.95 -> 16335.527 | I27: AFRMM | J27: 0.08 | K27: =(K16)*J27+20 -> 1031.58 | M27: Base de Cálculo PIS/COFINS | O27: =G22-O33-O31 -> 4.4838283 | P27: =P24*N29 -> 36008.927 | R27: AFRMM | S27: 0.08 | T27: =(T16+T17)*S27+21.2 -> 21.2 | V27: xxx | X27: 0 | AB27: AD. VALOREM | AC27: 0.001 | AD27: =AC27*K24 -> 480.37373 | AG27: =AG26*0.001 -> 670 | AH27: 570000
C28: 0.84 | I28: S.D.A./Despachante | K28: 2500 | M28: PIS | N28: 0.0165 | O28: =$O$27*N28 -> 0.073983168 | P28: =O28*$K$12 -> 9025.9465 | R28: S.D.A./Despachante | T28: =AD43*$D$30 -> 0 | V28: xxx | X28: 0 | AB28: ADICIONAL 25 TON | AC28: 0.15 | AD28: =AC25*AC28 -> 444.9 | AH28: =AH27*0.001 -> 570
F29: =5.0579/4.5-1 -> 0.12397778 | I29: Diferença frete internacional | J29: =K14*1.025 -> 5.1843475 | K29: =(J16*J29)-K16 -> 316.11875 | M29: COFINS | N29: 0.076 | O29: =$O$27*N29 -> 0.34077095 | P29: =O29*$K$12 -> 41574.056 | R29: Diferença frete internacional | S29: =T14*1.02 -> 5.159058 | T29: =(S16*S29)-T16 -> 0 | V29: xxx | X29: 0 | AB29: ICMS | AC29: 0.12 | AD29: =SUM(AD25:AD28)*AC29/0.88 -> 464.15621
A30: =C30 -> 0 | E30: =E24/18511.7-1 -> -0.07111222 | I30: Valores Agente de cargas | K30: =AD45*$D$15 -> 1800 | M30: Base de Cálculo ICMS | O30: =G22-O33 -> 4.55211 | P30: =P24*N31 -> 7107.0251 | R30: Valores Agente de cargas | T30: =AD45*$D$30 -> 0 | V30: xxx | X30: 0 | AB30: TOTAL | AD30: =SUM(AD25:AD28)/0.88 -> 3867.9684
A31: =C31 -> 0 | I31: Armazenagem PORTO | K31: =AD46*$D$15 -> 2600 | M31: ICMS | N31: 0.015 | O31: =$G$22*$N$31 -> 0.06828165 | P31: =O31*$K$12 -> 8330.3613 | R31: Armazenagem PORTO | T31: =AD46*$D$30 -> 0 | V31: xxx | X31: 0
A32: =C32 -> 0 | I32: Capatazia | K32: =AD47*$D$15 -> 1010 | M32: BC IPI | N32: 0.04 | O32: =G22/(1+N33) -> 4.55211 | R32: Capatazia | T32: =AD47*$D$30 -> 0 | V32: xxx | X32: 0 | AB32: CALCULO TRANSPORTADORA - IBITINGA
A33: =C32 -> 0 | F33: 0.08 | I33: Custo Desembaraço - Santos | K33: =K23+SUM(K25:K32) -> 488599.85 | M33: IPI | N33: =J20 -> 0 | O33: =N33*O32 -> 0 | P33: =O33*$K$12 -> 0 | R33: Custo Desembaraço - Santos | T33: =T23+SUM(T25:T32) -> #N/A | V33: xxx | X33: 0 | AB33: FRETE PESO | AC33: 6316 | AD33: =AC33 -> 6316
A34: =A31*A32 -> 0 | I34: Frete Interno | K34: =AD49*$D$15 -> 13000 | O34: =G22 -> 4.55211 | P34: 0 | R34: Frete Interno - Pouso Alegre | T34: =AD49*$D$30 -> 0 | V34: CUSTO TOTAL UNITÁRIO | X34: =X16+X17+X39+X40+X42+X44+X47+X48+X49 -> #N/A | Y34: =X34*T12 -> #N/A | AB34: PEDÁGIO | AC34: 866.8 | AD34: =AC34 -> 866.8
A35: =A31*A33 -> 0 | M35: Base de Calculo lucro real | O35: =P26 -> 22625.384 | P35: 59999.99 | V35: Valor Unitário USD / tx dolar di | X35: =X34/T14 -> #N/A | AB35: AD. VALOREM | AC35: 0.001 | AD35: =AC35*(K33+T33) -> #N/A
A36: =A35/A34-1 -> #DIV/0! | I36: Operador Logistico | M36: CCSLL | N36: 0.09 | O36: =P36/$K$12 -> 0.016690857 | P36: =O35*N36 -> 2036.2846 | R36: Operador Logistico | T36: 1000 | V36: Margem | W36: =X36/X34 -> #N/A | X36: =X37-X34 -> #N/A | Y36: =W36*Y37 -> #N/A | AB36: ADICIONAL 25 TON | AC36: 0.15 | AD36: =AC33*AC36 -> 947.4
A37: =A34-A35 -> 0 | I37: Operação de carga e descarga | M37: IR | N37: 0.15 | O37: =P37/$K$12 -> 0.027818095 | P37: =N37*O35 -> 3393.8076 | R37: Operação de carga e descarga | V37: PREÇO DE VENDA S/ Impostos | X37: =G37 -> 0 | Y37: =X37*T12 -> 0 | AB37: ICMS | AC37: 0.12 | AD37: =SUM(AD33:AD36)*AC37/0.88 -> #N/A
A38: =A37*A26 -> 0 | I38: coleta vazio | K38: 0 | M38: adicional de IR | N38: 0.1 | O38: =P38/$K$12 -> 0 | P38: =IF(O35>=P35,(O35-P35)*N38,IF(O35<P35,P34*N38)) -> 0 | R38: coleta vazio | V38: Base de Cálculo PIS/COFINS | X38: =G37-X44-X42 -> #N/A | AB38: TOTAL | AD38: =SUM(AD33:AD36)+AD22 -> #N/A
I39: CABOTAGEM | K39: 0 | M39: PREÇO DE VENDA | N39: =O39/5.45 -> 0.83524954 | O39: =G22 -> 4.55211 | P39: =O39*K12 -> 555357.42 | R39: CABOTAGEM | T39: =IF(C10="CABOTAGEM",AE17,IF(C10="IBITINGA",AE32,IF(C10="MINAS",AE22)))*$D$30 -> 0 | V39: PIS | W39: =VLOOKUP($C$29,'NCMS E ALÍQUOTAS'!$B$2:$O$2225,7,FALSE) -> #N/A | X39: =$X$38*W39 -> #N/A | Y39: =X39*$T$12 -> #N/A
I40: Custo Processo | K40: =SUM(K33:K39) -> 501599.85 | M40: Base de Calculo DIFAL | O40: =D23+P33 -> 555357.42 | P40: =O40/0.82 -> 677265.15 | R40: Custo Processo | T40: =SUM(T33:T39) -> #N/A | V40: COFINS | W40: =VLOOKUP($C$29,'NCMS E ALÍQUOTAS'!$B$2:$O$2225,8,FALSE) -> #N/A | X40: =$X$38*W40 -> #N/A | Y40: =X40*$T$12 -> #N/A
I41: Custo Total Unitário | K41: =K40/K12 -> 4.1114742 | M41: icms difal | N41: 0.18 | P41: =P40*N41 -> 121907.73 | R41: Custo Total Unitário | T41: =T40/T12 -> #N/A | V41: Base de Cálculo ICMS | X41: =P21-X44 -> #N/A
I42: (-) CRÉDITOS S/ INSUMOS | K42: =SUM(K43:K46) -> 43405.33 | M42: icms difal mg | N42: 0.04 | P42: =N42*P40 -> 27090.606 | R42: (-) CRÉDITOS S/ INSUMOS | T42: =SUM(T43:T46) -> #N/A | V42: ICMS | W42: =VLOOKUP($E$10,$AD$12:$AE$13,2,FALSE) -> 0.015 | X42: =$G$37*$W$42 -> 0 | Y42: =X42*$T$12 -> 0 | AB42: CUSTOS FIXOS
I43: (-) IPI | J43: =J20 -> 0 | K43: =K20 -> 0 | M43: TOTAL DIFAL | R43: (-) IPI | T43: =T20 -> #N/A | V43: BC IPI | X43: =P21/(1+W44) -> #N/A | AB43: S.D.A./Despachante | AD43: 2500
C44: =280/250 -> 1.12 | D44: =C32*C44 -> 0 | E44: 0.98 | I44: (-) PIS | J44: =J21 -> 0.021 | K44: =$J$44*K18 -> 7263.0432 | R44: (-) PIS | S44: 0 | T44: =$S$44*T18 -> 0 | V44: IPI | W44: =VLOOKUP($C$29,'NCMS E ALÍQUOTAS'!$B$2:$O$2225,4,FALSE) -> #N/A | X44: =W44*X43 -> #N/A | Y44: =X44*$T$12 -> #N/A
...

Sheet TABELA MATRIZ MG
A1: PRODUTO | B1: NCM | C1: II NCM | D1: IPI | E1: PIS | F1: COFINS | G1: PIS | H1: COFINS | I1: ICMS INTRA | J1: ICMS INTER | K1: Reg Espec INTRA | L1: Reg Espec INTER | M1: ICMS-ST | N1: MOQ | O1: LAI MEI | P1: TONGKHUAN | Q1: AUDREY | R1: DANIELLE | S1: EMMA/heitor | T1: MIIHYUEH | U1: AVANT | V1: KAYBEE | W1: GLOBAL | X1: MENOR VALOR FOB UNITÁRIO | Y1: VALOR FOB UNITÁRIO | Z1: FOB | AA1: FRETE INTERNACIONAL | AB1: TOTAL CIF USD | AC1: TOTAL CIF R$ | AD1: II | AE1: IPI | AF1: PIS | AG1: COFINS | AH1: TX SISCOMEX | AI1: AFRMM | AJ1: CAPATAZIAS | AK1: S.D.A./Despachante | AL1: Diferença frete int | AM1: Valores Agente de cargas | AN1: Armazenagem PORTO | AO1: FRETE RODVIÁRIO | AP1: OPERADOR LOGÍSTICO | AQ1: CREDITO PIS LUCRO REAL | AR1: CREDITO COFINS LUCRO REAL | AS1: CABOTAGEM | AT1: CUSTO DO PROCESSO R$ | AU1: CUSTO TOTAL UNITÁRIO R$ | AV1: COMISSÃO | AW1: CUSTO UNITÁRIO EM USD | AX1: Base de Cálculo PIS/COFINS | AY1: PIS | AZ1: COFINS | BA1: Base de Cálculo ICMS | BB1: ICMS | BC1: BC IPI | BD1: IPI | BE1: Base de Calculo IR | BF1: Base de Calculo csll | BG1: CSLL | BH1: IR | BI1: adicional IR | BJ1: custo VENDA | BK1: Custo total OPERAÇAO R$ | BL1: PERCENTUAL | BM1: PREÇO DE VENDA SUGERIDO USD | BN1: PREÇO DE VENDA TABELA USD | BO1: PREÇO DE VENDA JUROS TABELA USD | BP1: PREÇO DE VENDA SUGERIDO R$ | BQ1: PREÇO DE VENDA JUROS SUGERIDO R$ | BR1: PREÇO DE VENDA TABELA R$ | BS1: TOTAL VENDA SUGERIDA | BU1: TOTAL VENDA PREÇO TABELA | BV1: CUSTO TOTAL | BW1: custo total | BX1: margem | BY1: 59999.99
A2: COLCHA SOLTEIRO 60GSM SOLID | B2: 9404.40.00 | C2: 0.162 | D2: 0 | E2: 0.021 | F2: 0.0965 | G2: 0.0165 | H2: 0.076 | I2: 0.18 | J2: 0.04 | K2: 0.14 | L2: 0.015 | M2: N/A | N2: 9200 | O2: 3.05 | T2: 3.05 | X2: =MIN(O2:W2) -> 3.05 | Y2: =AVERAGE(O2:W2) -> 3.05 | Z2: =Y2*N2 -> 28060 | AA2: ='CALCULO GERAL'!$G$10 -> 6300 | AB2: =Z2+AA2 -> 34360 | AC2: =AB2*'CALCULO GERAL'!$C$11 -> 172452.84 | AD2: =AC2*C2 -> 27937.36 | AE2: =(AC2+AD2)*D2 -> 0 | AF2: =AC2*E2 -> 3621.5096 | AG2: =AC2*F2 -> 16641.699 | AH2: 154.23 | AI2: =((AA2*'CALCULO GERAL'!$C$11))*0.08+20 -> 2549.576 | AJ2: 1010 | AK2: 2500 | AL2: =(AA2*('CALCULO GERAL'!$C$11*1.02))-(AA2*'CALCULO GERAL'!$C$11) -> 632.394 | AM2: 1800 | AN2: 2600 | AO2: 9400 | AP2: 1000 | AQ2: =-AF2 -> -3621.5096 | AR2: =-AG2 -> -16641.699 | AT2: =SUM(AC2:AS2) -> 222036.4 | AU2: =IFERROR((AT2/N2),0) -> 24.134391 | AV2: =IFERROR((BS2*'CALCULO GERAL'!$E$11)/N2,0) -> 0.6615042 | AW2: =AU2/'CALCULO GERAL'!$C$11 -> 4.8086056 | AX2: =BP2-BB2-BD2*'CALCULO GERAL'!$C$11 -> 32.579082 | AY2: =AX2*G2 -> 0.53755485 | AZ2: =AX2*H2 -> 2.4760102 | BA2: =BP2-BD2 -> 33.07521 | BB2: =BA2*L2 -> 0.49612815 | BC2: =BP2/(1+D2) -> 33.07521 | BD2: =BC2*D2 -> 0 | BE2: =BT2 -> 82255.532 | BF2: =BT2 -> 82255.532 | BG2: =(BF2*0.09)/N2 -> 0.80467368 | BH2: =(BE2*0.15)/N2 -> 1.3411228 | BI2: =IF(BE2>=$BY$1,($BY$1-BE2)*0.1,IF(BE2<=$BY$1,($BY$1*0)))/N2 -> -0.24190806 | BJ2: =(AY2+AZ2+BB2+AV2+BD2+BG2+BH2+BI2) -> 6.0750858 | BK2: =BJ2+AU2 -> 30.209477 | BL2: 0.74 | BM2: =ROUND((AW2/BL2)+((AW2*BL2)*'CALCULO GERAL'!$E$11)/BL2,2) -> 6.59 | BN2: =BM2 -> 6.59 | BO2: =ROUND(FV(0.02,8,,BN2)*-1,3) -> 7.721 | BP2: =BM2*'CALCULO GERAL'!$C$11 -> 33.07521 | BQ2: =BO2*'CALCULO GERAL'!$C$11 -> 38.751699 | BR2: =BN2*'CALCULO GERAL'!$C$11 -> 33.07521 | BS2: =BP2*N2 -> 304291.93 | BT2: =BS2-AT2 -> 82255.532 | BU2: =BR2*N2 -> 304291.93 | BV2: =BK2*N2 -> 277927.19 | BW2: =BS2-BV2 -> 26364.742 | BX2: =(((BK2*N2)-BS2)/BS2*-1) -> 0.086642922 | BY2: =ROUND(BL2,2) -> 0.74 | CE2: =CC2/BY2 -> 0 | CF2: =100%-CE2 -> 1 | CG2: =AVERAGE(CF2,CD2) -> 1
A3: COLCHA CASAL 60GSM SOLID | B3: 9404.40.00 | C3: 0.162 | D3: 0 | E3: 0.021 | F3: 0.0965 | G3: 0.0165 | H3: 0.076 | I3: 0.18 | J3: 0.04 | K3: 0.14 | L3: 0.015 | M3: N/A | N3: 9200 | O3: 4.12 | T3: 4.12 | X3: =MIN(O3:W3) -> 4.12 | Y3: =AVERAGE(O3:W3) -> 4.12 | Z3: =Y3*N3 -> 37904 | AA3: ='CALCULO GERAL'!$G$10 -> 6300 | AB3: =Z3+AA3 -> 44204 | AC3: =AB3*'CALCULO GERAL'!$C$11 -> 221859.88 | AD3: =AC3*C3 -> 35941.3 | AE3: =(AC3+AD3)*D3 -> 0 | AF3: =AC3*E3 -> 4659.0574 | AG3: =AC3*F3 -> 21409.478 | AH3: 154.23 | AI3: =((AA3*'CALCULO GERAL'!$C$11))*0.08+20 -> 2549.576 | AJ3: 1010 | AK3: 2500 | AL3: =(AA3*('CALCULO GERAL'!$C$11*1.02))-(AA3*'CALCULO GERAL'!$C$11) -> 632.394 | AM3: 1800 | AN3: 2600 | AO3: 9400 | AP3: 1000 | AQ3: =-AF3 -> -4659.0574 | AR3: =-AG3 -> -21409.478 | AT3: =SUM(AC3:AS3) -> 279447.38 | AU3: =IFERROR((AT3/N3),0) -> 30.374715 | AV3: =IFERROR((BS3*'CALCULO GERAL'!$E$11)/N3,0) -> 0.833154 | AW3: =AU3/'CALCULO GERAL'!$C$11 -> 6.0519456 | AX3: =BP3-BB3-BD3*'CALCULO GERAL'!$C$11 -> 41.032835 | AY3: =AX3*G3 -> 0.67704177 | AZ3: =AX3*H3 -> 3.1184954 | BA3: =BP3-BD3 -> 41.6577 | BB3: =BA3*L3 -> 0.6248655 | BC3: =BP3/(1+D3) -> 41.6577 | BD3: =BC3*D3 -> 0 | BE3: =BU3*0.08 -> 30660.067 | BF3: =BU3*0.12 -> 45990.101 | BG3: =(BF3*0.09)/N3 -> 0.44990316 | BH3: =(BE3*0.15)/N3 -> 0.4998924 | BI3: =IF(BE3>=$BY$1,($BY$1-BE3)*0.1,IF(BE3<=$BY$1,($BY$1*0)))/N3 -> 0 | BJ3: =(AY3+AZ3+BB3+AV3+BD3+BG3+BH3+BI3) -> 6.2033523 | BK3: =BJ3+AU3 -> 36.578067 | BL3: 0.74 | BM3: =ROUND((AW3/BL3)+((AW3*BL3)*'CALCULO GERAL'!$E$11)/BL3,2) -> 8.3 | BN3: =BM3 -> 8.3 | BO3: =ROUND(FV(0.02,8,,BN3)*-1,3) -> 9.725 | BP3: =BM3*'CALCULO GERAL'!$C$11 -> 41.6577 | BQ3: =BO3*'CALCULO GERAL'!$C$11 -> 48.809775 | BR3: =BN3*'CALCULO GERAL'!$C$11 -> 41.6577 | BS3: =BP3*N3 -> 383250.84 | BT3: =BS3-AT3 -> 103803.46 | BU3: =BR3*N3 -> 383250.84 | BV3: =BK3*N3 -> 336518.22 | BW3: =BS3-BV3 -> 46732.623 | BX3: =(((BK3*N3)-BS3)/BS3*-1) -> 0.12193743 | BY3: =ROUND(BL3,2) -> 0.74 | CE3: =CC3/BY3 -> 0 | CF3: =100%-CE3 -> 1 | CG3: =AVERAGE(CF3,CD3) -> 1
A4: COLCHA QUEEN 60GSM SOLID | B4: 9404.40.00 | C4: 0.162 | D4: 0 | E4: 0.021 | F4: 0.0965 | G4: 0.0165 | H4: 0.076 | I4: 0.18 | J4: 0.04 | K4: 0.14 | L4: 0.015 | M4: N/A | N4: 9200 | O4: 4.6 | T4: 4.6 | X4: =MIN(O4:W4) -> 4.6 | Y4: =AVERAGE(O4:W4) -> 4.6 | Z4: =Y4*N4 -> 42320 | AA4: ='CALCULO GERAL'!$G$10 -> 6300 | AB4: =Z4+AA4 -> 48620 | AC4: =AB4*'CALCULO GERAL'!$C$11 -> 244023.78 | AD4: =AC4*C4 -> 39531.852 | AE4: =(AC4+AD4)*D4 -> 0 | AF4: =AC4*E4 -> 5124.4994 | AG4: =AC4*F4 -> 23548.295 | AH4: 154.23 | AI4: =((AA4*'CALCULO GERAL'!$C$11))*0.08+20 -> 2549.576 | AJ4: 1010 | AK4: 2500 | AL4: =(AA4*('CALCULO GERAL'!$C$11*1.02))-(AA4*'CALCULO GERAL'!$C$11) -> 632.394 | AM4: 1800 | AN4: 2600 | AO4: 9400 | AP4: 1000 | AQ4: =-AF4 -> -5124.4994 | AR4: =-AG4 -> -23548.295 | AT4: =SUM(AC4:AS4) -> 305201.83 | AU4: =IFERROR((AT4/N4),0) -> 33.174112 | AV4: =IFERROR((BS4*'CALCULO GERAL'!$E$11)/N4,0) -> 0.9094428 | AW4: =AU4/'CALCULO GERAL'!$C$11 -> 6.6097056 | AX4: =BP4-BB4-BD4*'CALCULO GERAL'!$C$11 -> 44.790058 | AY4: =AX4*G4 -> 0.73903596 | AZ4: =AX4*H4 -> 3.4040444 | BA4: =BP4-BD4 -> 45.47214 | BB4: =BA4*L4 -> 0.6820821 | BC4: =BP4/(1+D4) -> 45.47214 | BD4: =BC4*D4 -> 0 | BE4: =BU4*0.08 -> 33467.495 | BF4: =BU4*0.12 -> 50201.243 | BG4: =(BF4*0.09)/N4 -> 0.49109911 | BH4: =(BE4*0.15)/N4 -> 0.54566568 | BI4: =IF(BE4>=$BY$1,($BY$1-BE4)*0.1,IF(BE4<=$BY$1,($BY$1*0)))/N4 -> 0 | BJ4: =(AY4+AZ4+BB4+AV4+BD4+BG4+BH4+BI4) -> 6.77137 | BK4: =BJ4+AU4 -> 39.945482 | BL4: 0.74 | BM4: =ROUND((AW4/BL4)+((AW4*BL4)*'CALCULO GERAL'!$E$11)/BL4,2) -> 9.06 | BN4: =BM4 -> 9.06 | BO4: =ROUND(FV(0.02,8,,BN4)*-1,3) -> 10.615 | BP4: =BM4*'CALCULO GERAL'!$C$11 -> 45.47214 | BQ4: =BO4*'CALCULO GERAL'!$C$11 -> 53.276685 | BR4: =BN4*'CALCULO GERAL'!$C$11 -> 45.47214 | BS4: =BP4*N4 -> 418343.69 | BT4: =BS4-AT4 -> 113141.86 | BU4: =BR4*N4 -> 418343.69 | BV4: =BK4*N4 -> 367498.44 | BW4: =BS4-BV4 -> 50845.251 | BX4: =(((BK4*N4)-BS4)/BS4*-1) -> 0.12153942 | BY4: =ROUND(BL4,2) -> 0.74 | CE4: =CC4/BY4 -> 0 | CF4: =100%-CE4 -> 1 | CG4: =AVERAGE(CF4,CD4) -> 1
A5: COLCHA KING 60GSM SOLID | B5: 9404.40.00 | C5: 0.162 | D5: 0 | E5: 0.021 | F5: 0.0965 | G5: 0.0165 | H5: 0.076 | I5: 0.18 | J5: 0.04 | K5: 0.14 | L5: 0.015 | M5: N/A | N5: 9200 | O5: 5.1 | T5: 5.1 | X5: =MIN(O5:W5) -> 5.1 | Y5: =AVERAGE(O5:W5) -> 5.1 | Z5: =Y5*N5 -> 46920 | AA5: ='CALCULO GERAL'!$G$10 -> 6300 | AB5: =Z5+AA5 -> 53220 | AC5: =AB5*'CALCULO GERAL'!$C$11 -> 267111.18 | AD5: =AC5*C5 -> 43272.011 | AE5: =(AC5+AD5)*D5 -> 0 | AF5: =AC5*E5 -> 5609.3348 | AG5: =AC5*F5 -> 25776.229 | AH5: 154.23 | AI5: =((AA5*'CALCULO GERAL'!$C$11))*0.08+20 -> 2549.576 | AJ5: 1010 | AK5: 2500 | AL5: =(AA5*('CALCULO GERAL'!$C$11*1.02))-(AA5*'CALCULO GERAL'!$C$11) -> 632.394 | AM5: 1800 | AN5: 2600 | AO5: 9400 | AP5: 1000 | AQ5: =-AF5 -> -5609.3348 | AR5: =-AG5 -> -25776.229 | AT5: =SUM(AC5:AS5) -> 332029.39 | AU5: =IFERROR((AT5/N5),0) -> 36.090151 | AV5: =IFERROR((BS5*'CALCULO GERAL'!$E$11)/N5,0) -> 0.9897468 | AW5: =AU5/'CALCULO GERAL'!$C$11 -> 7.1907056 | AX5: =BP5-BB5-BD5*'CALCULO GERAL'!$C$11 -> 48.74503 | AY5: =AX5*G5 -> 0.80429299 | AZ5: =AX5*H5 -> 3.7046223 | BA5: =BP5-BD5 -> 49.48734 | BB5: =BA5*L5 -> 0.7423101 | BC5: =BP5/(1+D5) -> 49.48734 | BD5: =BC5*D5 -> 0 | BE5: =BU5*0.08 -> 36422.682 | BF5: =BU5*0.12 -> 54634.023 | BG5: =(BF5*0.09)/N5 -> 0.53446327 | BH5: =(BE5*0.15)/N5 -> 0.59384808 | BI5: =IF(BE5>=$BY$1,($BY$1-BE5)*0.1,IF(BE5<=$BY$1,($BY$1*0)))/N5 -> 0 | BJ5: =(AY5+AZ5+BB5+AV5+BD5+BG5+BH5+BI5) -> 7.3692835 | BK5: =BJ5+AU5 -> 43.459435 | BL5: 0.74 | BM5: =ROUND((AW5/BL5)+((AW5*BL5)*'CALCULO GERAL'!$E$11)/BL5,2) -> 9.86 | BN5: =BM5 -> 9.86 | BO5: =ROUND(FV(0.02,8,,BN5)*-1,3) -> 11.553 | BP5: =BM5*'CALCULO GERAL'!$C$11 -> 49.48734 | BQ5: =BO5*'CALCULO GERAL'!$C$11 -> 57.984507 | BR5: =BN5*'CALCULO GERAL'!$C$11 -> 49.48734 | BS5: =BP5*N5 -> 455283.53 | BT5: =BS5-AT5 -> 123254.14 | BU5: =BR5*N5 -> 455283.53 | BV5: =BK5*N5 -> 399826.8 | BW5: =BS5-BV5 -> 55456.728 | BX5: =(((BK5*N5)-BS5)/BS5*-1) -> 0.12180702 | BY5: =ROUND(BL5,2) -> 0.74 | CE5: =CC5/BY5 -> 0 | CF5: =100%-CE5 -> 1 | CG5: =AVERAGE(CF5,CD5) -> 1
A6: COLCHA SOLTEIRO 65GSM ESTAMPADA | B6: 9404.40.00 | C6: 0.162 | D6: 0 | E6: 0.021 | F6: 0.0965 | G6: 0.0165 | H6: 0.076 | I6: 0.18 | J6: 0.04 | K6: 0.14 | L6: 0.015 | M6: N/A | N6: 9200 | O6: 3.06 | T6: 3.06 | X6: =MIN(O6:W6) -> 3.06 | Y6: =AVERAGE(O6:W6) -> 3.06 | Z6: =Y6*N6 -> 28152 | AA6: ='CALCULO GERAL'!$G$10 -> 6300 | AB6: =Z6+AA6 -> 34452 | AC6: =AB6*'CALCULO GERAL'!$C$11 -> 172914.59 | AD6: =AC6*C6 -> 28012.163 | AE6: =(AC6+AD6)*D6 -> 0 | AF6: =AC6*E6 -> 3631.2063 | AG6: =AC6*F6 -> 16686.258 | AH6: 154.23 | AI6: =((AA6*'CALCULO GERAL'!$C$11))*0.08+20 -> 2549.576 | AJ6: 1010 | AK6: 2500 | AL6: =(AA6*('CALCULO GERAL'!$C$11*1.02))-(AA6*'CALCULO GERAL'!$C$11) -> 632.394 | AM6: 1800 | AN6: 2600 | AO6: 9400 | AP6: 1000 | AQ6: =-AF6 -> -3631.2063 | AR6: =-AG6 -> -16686.258 | AT6: =SUM(AC6:AS6) -> 222572.95 | AU6: =IFERROR((AT6/N6),0) -> 24.192712 | AV6: =IFERROR((BS6*'CALCULO GERAL'!$E$11)/N6,0) -> 0.6635118 | AW6: =AU6/'CALCULO GERAL'!$C$11 -> 4.8202256 | AX6: =BP6-BB6-BD6*'CALCULO GERAL'!$C$11 -> 32.677956 | AY6: =AX6*G6 -> 0.53918628 | AZ6: =AX6*H6 -> 2.4835247 | BA6: =BP6-BD6 -> 33.17559 | BB6: =BA6*L6 -> 0.49763385 | BC6: =BP6/(1+D6) -> 33.17559 | BD6: =BC6*D6 -> 0 | BE6: =BU6*0.08 -> 24417.234 | BF6: =BU6*0.12 -> 36625.851 | BG6: =(BF6*0.09)/N6 -> 0.35829637 | BH6: =(BE6*0.15)/N6 -> 0.39810708 | BI6: =IF(BE6>=$BY$1,($BY$1-BE6)*0.1,IF(BE6<=$BY$1,($BY$1*0)))/N6 -> 0 | BJ6: =(AY6+AZ6+BB6+AV6+BD6+BG6+BH6+BI6) -> 4.94026 | BK6: =BJ6+AU6 -> 29.132972 | BL6: 0.74 | BM6: =ROUND((AW6/BL6)+((AW6*BL6)*'CALCULO GERAL'!$E$11)/BL6,2) -> 6.61 | BN6: =BM6 -> 6.61 | BO6: =ROUND(FV(0.02,8,,BN6)*-1,3) -> 7.745 | BP6: =BM6*'CALCULO GERAL'!$C$11 -> 33.17559 | BQ6: =BO6*'CALCULO GERAL'!$C$11 -> 38.872155 | BR6: =BN6*'CALCULO GERAL'!$C$11 -> 33.17559 | BS6: =BP6*N6 -> 305215.43 | BT6: =BS6-AT6 -> 82642.477 | BU6: =BR6*N6 -> 305215.43 | BV6: =BK6*N6 -> 268023.34 | BW6: =BS6-BV6 -> 37192.084 | BX6: =(((BK6*N6)-BS6)/BS6*-1) -> 0.12185519 | BY6: =ROUND(BL6,2) -> 0.74 | CE6: =CC6/BY6 -> 0 | CF6: =100%-CE6 -> 1 | CG6: =AVERAGE(CF6,CD6) -> 1
A7: COLCHA CASAL 65GSM ESTAMPADA | B7: 9404.40.00 | C7: 0.162 | D7: 0 | E7: 0.021 | F7: 0.0965 | G7: 0.0165 | H7: 0.076 | I7: 0.18 | J7: 0.04 | K7: 0.14 | L7: 0.015 | M7: N/A | N7: 9200 | O7: 4.13 | T7: 4.13 | X7: =MIN(O7:W7) -> 4.13 | Y7: =AVERAGE(O7:W7) -> 4.13 | Z7: =Y7*N7 -> 37996 | AA7: ='CALCULO GERAL'!$G$10 -> 6300 | AB7: =Z7+AA7 -> 44296 | AC7: =AB7*'CALCULO GERAL'!$C$11 -> 222321.62 | AD7: =AC7*C7 -> 36016.103 | AE7: =(AC7+AD7)*D7 -> 0 | AF7: =AC7*E7 -> 4668.7541 | AG7: =AC7*F7 -> 21454.037 | AH7: 154.23 | AI7: =((AA7*'CALCULO GERAL'!$C$11))*0.08+20 -> 2549.576 | AJ7: 1010 | AK7: 2500 | AL7: =(AA7*('CALCULO GERAL'!$C$11*1.02))-(AA7*'CALCULO GERAL'!$C$11) -> 632.394 | AM7: 1800 | AN7: 2600 | AO7: 9400 | AP7: 1000 | AQ7: =-AF7 -> -4668.7541 | AR7: =-AG7 -> -21454.037 | AT7: =SUM(AC7:AS7) -> 279983.93 | AU7: =IFERROR((AT7/N7),0) -> 30.433036 | AV7: =IFERROR((BS7*'CALCULO GERAL'!$E$11)/N7,0) -> 0.8351616 | AW7: =AU7/'CALCULO GERAL'!$C$11 -> 6.0635656 | AX7: =BP7-BB7-BD7*'CALCULO GERAL'!$C$11 -> 41.131709 | AY7: =AX7*G7 -> 0.6786732 | AZ7: =AX7*H7 -> 3.1260099 | BA7: =BP7-BD7 -> 41.75808 | BB7: =BA7*L7 -> 0.6263712 | BC7: =BP7/(1+D7) -> 41.75808 | BD7: =BC7*D7 -> 0 | BE7: =BU7*0.08 -> 30733.947 | BF7: =BU7*0.12 -> 46100.92 | BG7: =(BF7*0.09)/N7 -> 0.45098726 | BH7: =(BE7*0.15)/N7 -> 0.50109696 | BI7: =IF(BE7>=$BY$1,($BY$1-BE7)*0.1,IF(BE7<=$BY$1,($BY$1*0)))/N7 -> 0 | BJ7: =(AY7+AZ7+BB7+AV7+BD7+BG7+BH7+BI7) -> 6.2183001 | BK7: =BJ7+AU7 -> 36.651336 | BL7: 0.74 | BM7: =ROUND((AW7/BL7)+((AW7*BL7)*'CALCULO GERAL'!$E$11)/BL7,2) -> 8.32 | BN7: =BM7 -> 8.32 | BO7: =ROUND(FV(0.02,8,,BN7)*-1,3) -> 9.748 | BP7: =BM7*'CALCULO GERAL'!$C$11 -> 41.75808 | BQ7: =BO7*'CALCULO GERAL'!$C$11 -> 48.925212 | BR7: =BN7*'CALCULO GERAL'!$C$11 -> 41.75808 | BS7: =BP7*N7 -> 384174.34 | BT7: =BS7-AT7 -> 104190.41 | BU7: =BR7*N7 -> 384174.34 | BV7: =BK7*N7 -> 337192.29 | BW7: =BS7-BV7 -> 46982.048 | BX7: =(((BK7*N7)-BS7)/BS7*-1) -> 0.12229356 | BY7: =ROUND(BL7,2) -> 0.74 | CE7: =CC7/BY7 -> 0 | CF7: =100%-CE7 -> 1 | CG7: =AVERAGE(CF7,CD7) -> 1
A8: COLCHA QUEEN 65GSM ESTAMPADA | B8: 9404.40.00 | C8: 0.162 | D8: 0 | E8: 0.021 | F8: 0.0965 | G8: 0.0165 | H8: 0.076 | I8: 0.18 | J8: 0.04 | K8: 0.14 | L8: 0.015 | M8: N/A | N8: 9200 | O8: 4.62 | T8: 4.62 | X8: =MIN(O8:W8) -> 4.62 | Y8: =AVERAGE(O8:W8) -> 4.62 | Z8: =Y8*N8 -> 42504 | AA8: ='CALCULO GERAL'!$G$10 -> 6300 | AB8: =Z8+AA8 -> 48804 | AC8: =AB8*'CALCULO GERAL'!$C$11 -> 244947.28 | AD8: =AC8*C8 -> 39681.459 | AE8: =(AC8+AD8)*D8 -> 0 | AF8: =AC8*E8 -> 5143.8928 | AG8: =AC8*F8 -> 23637.412 | AH8: 154.23 | AI8: =((AA8*'CALCULO GERAL'!$C$11))*0.08+20 -> 2549.576 | AJ8: 1010 | AK8: 2500 | AL8: =(AA8*('CALCULO GERAL'!$C$11*1.02))-(AA8*'CALCULO GERAL'!$C$11) -> 632.394 | AM8: 1800 | AN8: 2600 | AO8: 9400 | AP8: 1000 | AQ8: =-AF8 -> -5143.8928 | AR8: =-AG8 -> -23637.412 | AT8: =SUM(AC8:AS8) -> 306274.93 | AU8: =IFERROR((AT8/N8),0) -> 33.290754 | AV8: =IFERROR((BS8*'CALCULO GERAL'!$E$11)/N8,0) -> 0.913458 | AW8: =AU8/'CALCULO GERAL'!$C$11 -> 6.6329456 | AX8: =BP8-BB8-BD8*'CALCULO GERAL'!$C$11 -> 44.987806 | AY8: =AX8*G8 -> 0.74229881 | AZ8: =AX8*H8 -> 3.4190733 | BA8: =BP8-BD8 -> 45.6729 | BB8: =BA8*L8 -> 0.6850935 | BC8: =BP8/(1+D8) -> 45.6729 | BD8: =BC8*D8 -> 0 | BE8: =BU8*0.08 -> 33615.254 | BF8: =BU8*0.12 -> 50422.882 | BG8: =(BF8*0.09)/N8 -> 0.49326732 | BH8: =(BE8*0.15)/N8 -> 0.5480748 | BI8: =IF(BE8>=$BY$1,($BY$1-BE8)*0.1,IF(BE8<=$BY$1,($BY$1*0)))/N8 -> 0 | BJ8: =(AY8+AZ8+BB8+AV8+BD8+BG8+BH8+BI8) -> 6.8012657 | BK8: =BJ8+AU8 -> 40.092019 | BL8: 0.74 | BM8: =ROUND((AW8/BL8)+((AW8*BL8)*'CALCULO GERAL'!$E$11)/BL8,2) -> 9.1 | BN8: =BM8 -> 9.1 | BO8: =ROUND(FV(0.02,8,,BN8)*-1,3) -> 10.662 | BP8: =BM8*'CALCULO GERAL'!$C$11 -> 45.6729 | BQ8: =BO8*'CALCULO GERAL'!$C$11 -> 53.512578 | BR8: =BN8*'CALCULO GERAL'!$C$11 -> 45.6729 | BS8: =BP8*N8 -> 420190.68 | BT8: =BS8-AT8 -> 113915.75 | BU8: =BR8*N8 -> 420190.68 | BV8: =BK8*N8 -> 368846.58 | BW8: =BS8-BV8 -> 51344.101 | BX8: =(((BK8*N8)-BS8)/BS8*-1) -> 0.12219238 | BY8: =ROUND(BL8,2) -> 0.74 | CE8: =CC8/BY8 -> 0 | CF8: =100%-CE8 -> 1 | CG8: =AVERAGE(CF8,CD8) -> 1
A9: COLCHA KING 65GSM ESTAMPADA | B9: 9404.40.00 | C9: 0.162 | D9: 0 | E9: 0.021 | F9: 0.0965 | G9: 0.0165 | H9: 0.076 | I9: 0.18 | J9: 0.04 | K9: 0.14 | L9: 0.015 | M9: N/A | N9: 9200 | O9: 5.13 | T9: 5.13 | X9: =MIN(O9:W9) -> 5.13 | Y9: =AVERAGE(O9:W9) -> 5.13 | Z9: =Y9*N9 -> 47196 | AA9: ='CALCULO GERAL'!$G$10 -> 6300 | AB9: =Z9+AA9 -> 53496 | AC9: =AB9*'CALCULO GERAL'!$C$11 -> 268496.42 | AD9: =AC9*C9 -> 43496.421 | AE9: =(AC9+AD9)*D9 -> 0 | AF9: =AC9*E9 -> 5638.4249 | AG9: =AC9*F9 -> 25909.905 | AH9: 154.23 | AI9: =((AA9*'CALCULO GERAL'!$C$11))*0.08+20 -> 2549.576 | AJ9: 1010 | AK9: 2500 | AL9: =(AA9*('CALCULO GERAL'!$C$11*1.02))-(AA9*'CALCULO GERAL'!$C$11) -> 632.394 | AM9: 1800 | AN9: 2600 | AO9: 9400 | AP9: 1000 | AQ9: =-AF9 -> -5638.4249 | AR9: =-AG9 -> -25909.905 | AT9: =SUM(AC9:AS9) -> 333639.04 | AU9: =IFERROR((AT9/N9),0) -> 36.265114 | AV9: =IFERROR((BS9*'CALCULO GERAL'!$E$11)/N9,0) -> 0.9947658 | AW9: =AU9/'CALCULO GERAL'!$C$11 -> 7.2255656 | AX9: =BP9-BB9-BD9*'CALCULO GERAL'!$C$11 -> 48.992216 | AY9: =AX9*G9 -> 0.80837156 | AZ9: =AX9*H9 -> 3.7234084 | BA9: =BP9-BD9 -> 49.73829 | BB9: =BA9*L9 -> 0.74607435 | BC9: =BP9/(1+D9) -> 49.73829 | BD9: =BC9*D9 -> 0 | BE9: =BU9*0.08 -> 36607.381 | BF9: =BU9*0.12 -> 54911.072 | BG9: =(BF9*0.09)/N9 -> 0.53717353 | BH9: =(BE9*0.15)/N9 -> 0.59685948 | BI9: =IF(BE9>=$BY$1,($BY$1-BE9)*0.1,IF(BE9<=$BY$1,($BY$1*0)))/N9 -> 0 | BJ9: =(AY9+AZ9+BB9+AV9+BD9+BG9+BH9+BI9) -> 7.4066531 | BK9: =BJ9+AU9 -> 43.671767 | BL9: 0.74 | BM9: =ROUND((AW9/BL9)+((AW9*BL9)*'CALCULO GERAL'!$E$11)/BL9,2) -> 9.91 | BN9: =BM9 -> 9.91 | BO9: =ROUND(FV(0.02,8,,BN9)*-1,3) -> 11.611 | BP9: =BM9*'CALCULO GERAL'!$C$11 -> 49.73829 | BQ9: =BO9*'CALCULO GERAL'!$C$11 -> 58.275609 | BR9: =BN9*'CALCULO GERAL'!$C$11 -> 49.73829 | BS9: =BP9*N9 -> 457592.27 | BT9: =BS9-AT9 -> 123953.22 | BU9: =BR9*N9 -> 457592.27 | BV9: =BK9*N9 -> 401780.25 | BW9: =BS9-BV9 -> 55812.015 | BX9: =(((BK9*N9)-BS9)/BS9*-1) -> 0.12196888 | BY9: =ROUND(BL9,2) -> 0.74 | CE9: =CC9/BY9 -> 0 | CF9: =100%-CE9 -> 1 | CG9: =AVERAGE(CF9,CD9) -> 1
A10: COLCHA SOLTEIRO 70GSM SOLID 3D | B10: 9404.40.00 | C10: 0.162 | D10: 0 | E10: 0.021 | F10: 0.0965 | G10: 0.0165 | H10: 0.076 | I10: 0.18 | J10: 0.04 | K10: 0.14 | L10: 0.015 | M10: N/A | N10: 6000 | O10: 4.71 | T10: 4.71 | X10: =MIN(O10:W10) -> 4.71 | Y10: =AVERAGE(O10:W10) -> 4.71 | Z10: =Y10*N10 -> 28260 | AA10: ='CALCULO GERAL'!$G$10 -> 6300 | AB10: =Z10+AA10 -> 34560 | AC10: =AB10*'CALCULO GERAL'!$C$11 -> 173456.64 | AD10: =AC10*C10 -> 28099.976 | AE10: =(AC10+AD10)*D10 -> 0 | AF10: =AC10*E10 -> 3642.5894 | AG10: =AC10*F10 -> 16738.566 | AH10: 154.23 | AI10: =((AA10*'CALCULO GERAL'!$C$11))*0.08+20 -> 2549.576 | AJ10: 1010 | AK10: 2500 | AL10: =(AA10*('CALCULO GERAL'!$C$11*1.02))-(AA10*'CALCULO GERAL'!$C$11) -> 632.394 | AM10: 1800 | AN10: 2600 | AO10: 9400 | AP10: 1000 | AQ10: =-AF10 -> -3642.5894 | AR10: =-AG10 -> -16738.566 | AT10: =SUM(AC10:AS10) -> 223202.82 | AU10: =IFERROR((AT10/N10),0) -> 37.200469 | AV10: =IFERROR((BS10*'CALCULO GERAL'!$E$11)/N10,0) -> 1.0198608 | AW10: =AU10/'CALCULO GERAL'!$C$11 -> 7.4119285 | AX10: =BP10-BB10-BD10*'CALCULO GERAL'!$C$11 -> 50.228144 | AY10: =AX10*G10 -> 0.82876438 | AZ10: =AX10*H10 -> 3.817339 | BA10: =BP10-BD10 -> 50.99304 | BB10: =BA10*L10 -> 0.7648956 | BC10: =BP10/(1+D10) -> 50.99304 | BD10: =BC10*D10 -> 0 | BE10: =BU10*0.08 -> 24476.659 | BF10: =BU10*0.12 -> 36714.989 | BG10: =(BF10*0.09)/N10 -> 0.55072483 | BH10: =(BE10*0.15)/N10 -> 0.61191648 | BI10: =IF(BE10>=$BY$1,($BY$1-BE10)*0.1,IF(BE10<=$BY$1,($BY$1*0)))/N10 -> 0 | BJ10: =(AY10+AZ10+BB10+AV10+BD10+BG10+BH10+BI10) -> 7.5935011 | BK10: =BJ10+AU10 -> 44.79397 | BL10: 0.74 | BM10: =ROUND((AW10/BL10)+((AW10*BL10)*'CALCULO GERAL'!$E$11)/BL10,2) -> 10.16 | BN10: =BM10 -> 10.16 | BO10: =ROUND(FV(0.02,8,,BN10)*-1,3) -> 11.904 | BP10: =BM10*'CALCULO GERAL'!$C$11 -> 50.99304 | BQ10: =BO10*'CALCULO GERAL'!$C$11 -> 59.746176 | BR10: =BN10*'CALCULO GERAL'!$C$11 -> 50.99304 | BS10: =BP10*N10 -> 305958.24 | BT10: =BS10-AT10 -> 82755.424 | BU10: =BR10*N10 -> 305958.24 | BV10: =BK10*N10 -> 268763.82 | BW10: =BS10-BV10 -> 37194.418 | BX10: =(((BK10*N10)-BS10)/BS10*-1) -> 0.12156698 | BY10: =ROUND(BL10,2) -> 0.74 | CE10: =CC10/BY10 -> 0 | CF10: =100%-CE10 -> 1 | CG10: =AVERAGE(CF10,CD10) -> 1
A11: COLCHA CASAL 70GSM SOLID 3D | B11: 9404.40.00 | C11: 0.162 | D11: 0 | E11: 0.021 | F11: 0.0965 | G11: 0.0165 | H11: 0.076 | I11: 0.18 | J11: 0.04 | K11: 0.14 | L11: 0.015 | M11: N/A | N11: 6000 | O11: 6.22 | T11: 6.22 | X11: =MIN(O11:W11) -> 6.22 | Y11: =AVERAGE(O11:W11) -> 6.22 | Z11: =Y11*N11 -> 37320 | AA11: ='CALCULO GERAL'!$G$10 -> 6300 | AB11: =Z11+AA11 -> 43620 | AC11: =AB11*'CALCULO GERAL'!$C$11 -> 218928.78 | AD11: =AC11*C11 -> 35466.462 | AE11: =(AC11+AD11)*D11 -> 0 | AF11: =AC11*E11 -> 4597.5044 | AG11: =AC11*F11 -> 21126.627 | AH11: 154.23 | AI11: =((AA11*'CALCULO GERAL'!$C$11))*0.08+20 -> 2549.576 | AJ11: 1010 | AK11: 2500 | AL11: =(AA11*('CALCULO GERAL'!$C$11*1.02))-(AA11*'CALCULO GERAL'!$C$11) -> 632.394 | AM11: 1800 | AN11: 2600 | AO11: 9400 | AP11: 1000 | AQ11: =-AF11 -> -4597.5044 | AR11: =-AG11 -> -21126.627 | AT11: =SUM(AC11:AS11) -> 276041.44 | AU11: =IFERROR((AT11/N11),0) -> 46.006907 | AV11: =IFERROR((BS11*'CALCULO GERAL'!$E$11)/N11,0) -> 1.2617766 | AW11: =AU11/'CALCULO GERAL'!$C$11 -> 9.1665485 | AX11: =BP11-BB11-BD11*'CALCULO GERAL'!$C$11 -> 62.142498 | AY11: =AX11*G11 -> 1.0253512 | AZ11: =AX11*H11 -> 4.7228298 | BA11: =BP11-BD11 -> 63.08883 | BB11: =BA11*L11 -> 0.94633245 | BC11: =BP11/(1+D11) -> 63.08883 | BD11: =BC11*D11 -> 0 | BE11: =BU11*0.08 -> 30282.638 | BF11: =BU11*0.12 -> 45423.958 | BG11: =(BF11*0.09)/N11 -> 0.68135936 | BH11: =(BE11*0.15)/N11 -> 0.75706596 | BI11: =IF(BE11>=$BY$1,($BY$1-BE11)*0.1,IF(BE11<=$BY$1,($BY$1*0)))/N11 -> 0 | BJ11: =(AY11+AZ11+BB11+AV11+BD11+BG11+BH11+BI11) -> 9.3947154 | BK11: =BJ11+AU11 -> 55.401622 | BL11: 0.74 | BM11: =ROUND((AW11/BL11)+((AW11*BL11)*'CALCULO GERAL'!$E$11)/BL11,2) -> 12.57 | BN11: =BM11 -> 12.57 | BO11: =ROUND(FV(0.02,8,,BN11)*-1,3) -> 14.728 | BP11: =BM11*'CALCULO GERAL'!$C$11 -> 63.08883 | BQ11: =BO11*'CALCULO GERAL'!$C$11 -> 73.919832 | BR11: =BN11*'CALCULO GERAL'!$C$11 -> 63.08883 | BS11: =BP11*N11 -> 378532.98 | BT11: =BS11-AT11 -> 102491.54 | BU11: =BR11*N11 -> 378532.98 | BV11: =BK11*N11 -> 332409.73 | BW11: =BS11-BV11 -> 46123.245 | BX11: =(((BK11*N11)-BS11)/BS11*-1) -> 0.12184736 | BY11: =ROUND(BL11,2) -> 0.74 | CE11: =CC11/BY11 -> 0 | CF11: =100%-CE11 -> 1 | CG11: =AVERAGE(CF11,CD11) -> 1
A12: COLCHA QUEEN 70GSM SOLID 3D | B12: 9404.40.00 | C12: 0.162 | D12: 0 | E12: 0.021 | F12: 0.0965 | G12: 0.0165 | H12: 0.076 | I12: 0.18 | J12: 0.04 | K12: 0.14 | L12: 0.015 | M12: N/A | N12: 6000 | O12: 6.74 | T12: 6.74 | X12: =MIN(O12:W12) -> 6.74 | Y12: =AVERAGE(O12:W12) -> 6.74 | Z12: =Y12*N12 -> 40440 | AA12: ='CALCULO GERAL'!$G$10 -> 6300 | AB12: =Z12+AA12 -> 46740 | AC12: =AB12*'CALCULO GERAL'!$C$11 -> 234588.06 | AD12: =AC12*C12 -> 38003.266 | AE12: =(AC12+AD12)*D12 -> 0 | AF12: =AC12*E12 -> 4926.3493 | AG12: =AC12*F12 -> 22637.748 | AH12: 154.23 | AI12: =((AA12*'CALCULO GERAL'!$C$11))*0.08+20 -> 2549.576 | AJ12: 1010 | AK12: 2500 | AL12: =(AA12*('CALCULO GERAL'!$C$11*1.02))-(AA12*'CALCULO GERAL'!$C$11) -> 632.394 | AM12: 1800 | AN12: 2600 | AO12: 9400 | AP12: 1000 | AQ12: =-AF12 -> -4926.3493 | AR12: =-AG12 -> -22637.748 | AT12: =SUM(AC12:AS12) -> 294237.53 | AU12: =IFERROR((AT12/N12),0) -> 49.039588 | AV12: =IFERROR((BS12*'CALCULO GERAL'!$E$11)/N12,0) -> 1.345092 | AW12: =AU12/'CALCULO GERAL'!$C$11 -> 9.7707885 | AX12: =BP12-BB12-BD12*'CALCULO GERAL'!$C$11 -> 66.245781 | AY12: =AX12*G12 -> 1.0930554 | AZ12: =AX12*H12 -> 5.0346794 | BA12: =BP12-BD12 -> 67.2546 | BB12: =BA12*L12 -> 1.008819 | BC12: =BP12/(1+D12) -> 67.2546 | BD12: =BC12*D12 -> 0 | BE12: =BU12*0.08 -> 32282.208 | BF12: =BU12*0.12 -> 48423.312 | BG12: =(BF12*0.09)/N12 -> 0.72634968 | BH12: =(BE12*0.15)/N12 -> 0.8070552 | BI12: =IF(BE12>=$BY$1,($BY$1-BE12)*0.1,IF(BE12<=$BY$1,($BY$1*0)))/N12 -> 0 | BJ12: =(AY12+AZ12+BB12+AV12+BD12+BG12+BH12+BI12) -> 10.015051 | BK12: =BJ12+AU12 -> 59.054638 | BL12: 0.74 | BM12: =ROUND((AW12/BL12)+((AW12*BL12)*'CALCULO GERAL'!$E$11)/BL12,2) -> 13.4 | BN12: =BM12 -> 13.4 | BO12: =ROUND(FV(0.02,8,,BN12)*-1,3) -> 15.7 | BP12: =BM12*'CALCULO GERAL'!$C$11 -> 67.2546 | BQ12: =BO12*'CALCULO GERAL'!$C$11 -> 78.7983 | BR12: =BN12*'CALCULO GERAL'!$C$11 -> 67.2546 | BS12: =BP12*N12 -> 403527.6 | BT12: =BS12-AT12 -> 109290.07 | BU12: =BR12*N12 -> 403527.6 | BV12: =BK12*N12 -> 354327.83 | BW12: =BS12-BV12 -> 49199.771 | BX12: =(((BK12*N12)-BS12)/BS12*-1) -> 0.12192418 | BY12: =ROUND(BL12,2) -> 0.74 | CE12: =CC12/BY12 -> 0 | CF12: =100%-CE12 -> 1 | CG12: =AVERAGE(CF12,CD12) -> 1
A13: COLCHA KING 70GSM SOLID 3D | B13: 9404.40.00 | C13: 0.162 | D13: 0 | E13: 0.021 | F13: 0.0965 | G13: 0.0165 | H13: 0.076 | I13: 0.18 | J13: 0.04 | K13: 0.14 | L13: 0.015 | M13: N/A | N13: 6000 | O13: 7.57 | T13: 7.57 | X13: =MIN(O13:W13) -> 7.57 | Y13: =AVERAGE(O13:W13) -> 7.57 | Z13: =Y13*N13 -> 45420 | AA13: ='CALCULO GERAL'!$G$10 -> 6300 | AB13: =Z13+AA13 -> 51720 | AC13: =AB13*'CALCULO GERAL'!$C$11 -> 259582.68 | AD13: =AC13*C13 -> 42052.394 | AE13: =(AC13+AD13)*D13 -> 0 | AF13: =AC13*E13 -> 5451.2363 | AG13: =AC13*F13 -> 25049.729 | AH13: 154.23 | AI13: =((AA13*'CALCULO GERAL'!$C$11))*0.08+20 -> 2549.576 | AJ13: 1010 | AK13: 2500 | AL13: =(AA13*('CALCULO GERAL'!$C$11*1.02))-(AA13*'CALCULO GERAL'!$C$11) -> 632.394 | AM13: 1800 | AN13: 2600 | AO13: 9400 | AP13: 1000 | AQ13: =-AF13 -> -5451.2363 | AR13: =-AG13 -> -25049.729 | AT13: =SUM(AC13:AS13) -> 323281.27 | AU13: =IFERROR((AT13/N13),0) -> 53.880212 | AV13: =IFERROR((BS13*'CALCULO GERAL'!$E$11)/N13,0) -> 1.4775936 | AW13: =AU13/'CALCULO GERAL'!$C$11 -> 10.735249 | AX13: =BP13-BB13-BD13*'CALCULO GERAL'!$C$11 -> 72.771485 | AY13: =AX13*G13 -> 1.2007295 | AZ13: =AX13*H13 -> 5.5306328 | BA13: =BP13-BD13 -> 73.87968 | BB13: =BA13*L13 -> 1.1081952 | BC13: =BP13/(1+D13) -> 73.87968 | BD13: =BC13*D13 -> 0 | BE13: =BU13*0.08 -> 35462.246 | BF13: =BU13*0.12 -> 53193.37 | BG13: =(BF13*0.09)/N13 -> 0.79790054 | BH13: =(BE13*0.15)/N13 -> 0.88655616 | BI13: =IF(BE13>=$BY$1,($BY$1-BE13)*0.1,IF(BE13<=$BY$1,($BY$1*0)))/N13 -> 0 | BJ13: =(AY13+AZ13+BB13+AV13+BD13+BG13+BH13+BI13) -> 11.001608 | BK13: =BJ13+AU13 -> 64.88182 | BL13: 0.74 | BM13: =ROUND((AW13/BL13)+((AW13*BL13)*'CALCULO GERAL'!$E$11)/BL13,2) -> 14.72 | BN13: =BM13 -> 14.72 | BO13: =ROUND(FV(0.02,8,,BN13)*-1,3) -> 17.247 | BP13: =BM13*'CALCULO GERAL'!$C$11 -> 73.87968 | BQ13: =BO13*'CALCULO GERAL'!$C$11 -> 86.562693 | BR13: =BN13*'CALCULO GERAL'!$C$11 -> 73.87968 | BS13: =BP13*N13 -> 443278.08 | BT13: =BS13-AT13 -> 119996.81 | BU13: =BR13*N13 -> 443278.08 | BV13: =BK13*N13 -> 389290.92 | BW13: =BS13-BV13 -> 53987.159 | BX13: =(((BK13*N13)-BS13)/BS13*-1) -> 0.12179073 | BY13: =ROUND(BL13,2) -> 0.74 | CE13: =CC13/BY13 -> 0 | CF13: =100%-CE13 -> 1 | CG13: =AVERAGE(CF13,CD13) -> 1
A14: COLCHA SOLTEIRO 70GSM SOLID BULLET | B14: 9404.40.00 | C14: 0.162 | D14: 0 | E14: 0.021 | F14: 0.0965 | G14: 0.0165 | H14: 0.076 | I14: 0.18 | J14: 0.04 | K14: 0.14 | L14: 0.015 | M14: N/A | N14: 8000 | O14: 3.28 | T14: 3.28 | X14: =MIN(O14:W14) -> 3.28 | Y14: =AVERAGE(O14:W14) -> 3.28 | Z14: =Y14*N14 -> 26240 | AA14: ='CALCULO GERAL'!$G$10 -> 6300 | AB14: =Z14+AA14 -> 32540 | AC14: =AB14*'CALCULO GERAL'!$C$11 -> 163318.26 | AD14: =AC14*C14 -> 26457.558 | AE14: =(AC14+AD14)*D14 -> 0 | AF14: =AC14*E14 -> 3429.6835 | AG14: =AC14*F14 -> 15760.212 | AH14: 154.23 | AI14: =((AA14*'CALCULO GERAL'!$C$11))*0.08+20 -> 2549.576 | AJ14: 1010 | AK14: 2500 | AL14: =(AA14*('CALCULO GERAL'!$C$11*1.02))-(AA14*'CALCULO GERAL'!$C$11) -> 632.394 | AM14: 1800 | AN14: 2600 | AO14: 9400 | AP14: 1000 | AQ14: =-AF14 -> -3429.6835 | AR14: =-AG14 -> -15760.212 | AT14: =SUM(AC14:AS14) -> 211422.02 | AU14: =IFERROR((AT14/N14),0) -> 26.427752 | AV14: =IFERROR((BS14*'CALCULO GERAL'!$E$11)/N14,0) -> 0.7247436 | AW14: =AU14/'CALCULO GERAL'!$C$11 -> 5.2655414 | AX14: =BP14-BB14-BD14*'CALCULO GERAL'!$C$11 -> 35.693622 | AY14: =AX14*G14 -> 0.58894477 | AZ14: =AX14*H14 -> 2.7127153 | BA14: =BP14-BD14 -> 36.23718 | BB14: =BA14*L14 -> 0.5435577 | BC14: =BP14/(1+D14) -> 36.23718 | BD14: =BC14*D14 -> 0 | BE14: =BU14*0.08 -> 23191.795 | BF14: =BU14*0.12 -> 34787.693 | BG14: =(BF14*0.09)/N14 -> 0.39136154 | BH14: =(BE14*0.15)/N14 -> 0.43484616 | BI14: =IF(BE14>=$BY$1,($BY$1-BE14)*0.1,IF(BE14<=$BY$1,($BY$1*0)))/N14 -> 0 | BJ14: =(AY14+AZ14+BB14+AV14+BD14+BG14+BH14+BI14) -> 5.3961691 | BK14: =BJ14+AU14 -> 31.823921 | BL14: 0.74 | BM14: =ROUND((AW14/BL14)+((AW14*BL14)*'CALCULO GERAL'!$E$11)/BL14,2) -> 7.22 | BN14: =BM14 -> 7.22 | BO14: =ROUND(FV(0.02,8,,BN14)*-1,3) -> 8.459 | BP14: =BM14*'CALCULO GERAL'!$C$11 -> 36.23718 | BQ14: =BO14*'CALCULO GERAL'!$C$11 -> 42.455721 | BR14: =BN14*'CALCULO GERAL'!$C$11 -> 36.23718 | BS14: =BP14*N14 -> 289897.44 | BT14: =BS14-AT14 -> 78475.422 | BU14: =BR14*N14 -> 289897.44 | BV14: =BK14*N14 -> 254591.37 | BW14: =BS14-BV14 -> 35306.069 | BX14: =(((BK14*N14)-BS14)/BS14*-1) -> 0.12178814 | BY14: =ROUND(BL14,2) -> 0.74 | CE14: =CC14/BY14 -> 0 | CF14: =100%-CE14 -> 1 | CG14: =AVERAGE(CF14,CD14) -> 1
